Workbook

Sheet 總表
A1: 房號 | B1: 編號 | C1: 姓名 | D1: 單位 | E1: 性別 | F1: 青島金水皇冠假日飯店房號 | G1: 濟南飯店房號 | H1: 桌次 | I1: 晚宴座位 | J1: 課程分組 | K1: 組長 | L1: 備註 | M1: 車廂 | N1: 座位 | O1: 遊覽車次 | P1: 回程車廂 | Q1: 回程座位
A2: 1 | B2: 1 | C2: 許智雄 | D2: 高天通訊處 | E2: 男 | F2: 920 | G2: 2323 | H2: 第1桌 | I2: 第9桌 | J2: 第9組 | K2: 組長 | M2: 14 | N2: 04D | O2: 第一車 | P2: 02 | Q2: 01F
A3: 1 | B3: 2 | C3: 謝政男 | D3: 高天通訊處 | E3: 男 | F3: 920 | G3: 2323 | H3: 第1桌 | I3: 第6桌 | J3: 第6組 | M3: 14 | N3: 04C | O3: 第一車 | P3: 02 | Q3: 01C
A4: 2 | B4: 3 | C4: 何宜家 | D4: 高天通訊處 | E4: 女 | F4: 707 | G4: 2325 | H4: 第1桌 | I4: 主桌 | M4: 14 | N4: 04B | O4: 第一車 | P4: 02 | Q4: 01B
A5: 2 | B5: 4 | C5: 蕭宇晴 | D5: 高天通訊處 | E5: 女 | F5: 707 | G5: 2325 | H5: 第1桌 | I5: 第2桌 | J5: 第2組 | M5: 14 | N5: 05C | O5: 第一車 | P5: 02 | Q5: 02D
A6: 3 | B6: 5 | C6: 蕭如菁 | D6: 高天通訊處 | E6: 女 | F6: 915 | G6: 2326 | H6: 第1桌 | I6: 第3桌 | J6: 第3組 | M6: 14 | N6: 04F | O6: 第一車 | P6: 02 | Q6: 02A
A7: 3 | B7: 6 | C7: 何宜庭 | D7: 高天通訊處 | E7: 女 | F7: 915 | G7: 2326 | H7: 第1桌 | I7: 第8桌 | J7: 第8組 | M7: 14 | N7: 05B | O7: 第一車 | P7: 02 | Q7: 02C
A8: 4 | B8: 7 | C8: 戴東志 | D8: 高天通訊處 | E8: 男 | F8: 517 | G8: 2328 | H8: 第1桌 | I8: 第1桌 | J8: 第1組 | M8: 14 | N8: 04A | O8: 第一車 | P8: 02 | Q8: 01A
A9: 4 | B9: 8 | C9: 詹政杰 | D9: 高天通訊處 | E9: 男 | F9: 517 | G9: 2328 | H9: 第1桌 | I9: 第7桌 | J9: 第7組 | M9: 14 | N9: 05A | O9: 第一車 | P9: 02 | Q9: 02B
A10: 5 | B10: 9 | C10: 吳睿綝 | D10: 高天通訊處 | E10: 女 | F10: 908 | G10: 2329 | H10: 第1桌 | I10: 第9桌 | J10: 第9組 | M10: 14 | N10: 05D | O10: 第一車 | P10: 02 | Q10: 02F
A11: 5 | B11: 10 | C11: 陳懷柔 | D11: 高天通訊處 | E11: 女 | F11: 908 | G11: 2329 | H11: 第1桌 | I11: 第7桌 | J11: 第7組 | M11: 14 | N11: 05F | O11: 第一車 | P11: 02 | Q11: 03A
A12: 6 | B12: 11 | C12: 黃柏瑞 | D12: 高貴通訊處 | E12: 男 | F12: 720 | G12: 2330 | H12: 第2桌 | I12: 第1桌 | J12: 第1組 | K12: 組長 | M12: 14 | N12: 06A | O12: 第一車 | P12: 02 | Q12: 03B
A13: 6 | B13: 12 | C13: 陳其呈 | D13: 高貴通訊處 | E13: 男 | F13: 720 | G13: 2330 | H13: 第2桌 | I13: 第2桌 | J13: 第2組 | M13: 14 | N13: 06B | O13: 第一車 | P13: 02 | Q13: 04A
A14: 7 | B14: 13 | C14: 陳武均 | D14: 富予二通訊處 | E14: 男 | F14: 515 | G14: 2331 | H14: 第6桌 | I14: 第5桌 | J14: 第5組 | M14: 14 | N14: 06C | O14: 第二車 | P14: 02 | Q14: 04B
A15: 7 | B15: 14 | C15: 陳尚禾 | D15: 富予二通訊處 | E15: 男 | F15: 515 | G15: 2331 | H15: 第6桌 | I15: 第5桌 | J15: 第5組 | M15: 14 | N15: 06D | O15: 第二車 | P15: 02 | Q15: 04C
A16: 8 | B16: 15 | C16: 陳昶聿 | D16: 富予二通訊處 | E16: 男 | F16: 511 | G16: 2503 | H16: 第6桌 | I16: 第7桌 | J16: 第7組 | K16: 組長 | M16: 14 | N16: 07A | O16: 第二車 | P16: 02 | Q16: 04F
A17: 8 | B17: 16 | C17: 宋里安 | D17: 富予二通訊處 | E17: 男 | F17: 511 | G17: 2503 | H17: 第6桌 | I17: 第3桌 | J17: 第3組 | K17: 組長 | M17: 14 | N17: 07C | O17: 第二車 | P17: 02 | Q17: 05B
A18: 9 | B18: 17 | C18: 賴芯甯 | D18: 富予二通訊處 | E18: 女 | F18: 617 | G18: 2506 | H18: 第6桌 | I18: 第2桌 | J18: 第2組 | M18: 14 | N18: 06F | O18: 第二車 | P18: 02 | Q18: 04D
A19: 9 | B19: 18 | C19: 高泰琳 | D19: 富予二通訊處 | E19: 女 | F19: 617 | G19: 2506 | H19: 第6桌 | I19: 第4桌 | J19: 第4組 | M19: 14 | N19: 07D | O19: 第二車 | P19: 02 | Q19: 05C
A20: 10 | B20: 19 | C20: 許瓊云 | D20: 富予二通訊處 | E20: 女 | F20: 917 | G20: 2508 | H20: 第6桌 | I20: 第6桌 | J20: 第6組 | M20: 14 | N20: 07B | O20: 第二車 | P20: 02 | Q20: 05A
A21: 10 | B21: 20 | C21: 王姵慈 | D21: 富吳通訊處 | E21: 女 | F21: 917 | G21: 2508 | H21: 第8桌 | I21: 第2桌 | J21: 第2組 | M21: 14 | N21: 12F | O21: 第二車 | P21: 02 | Q21: 10A
A22: 11 | B22: 21 | C22: 賴含怡 | D22: 富則通訊處 | E22: 女 | F22: 616 | G22: 2509 | H22: 第7桌 | I22: 第4桌 | J22: 第4組 | M22: 14 | N22: 14D | O22: 第二車 | P22: 02 | Q22: 11F
A23: 11 | B23: 22 | C23: 吳佩姗 | D23: 富吳通訊處 | E23: 女 | F23: 616 | G23: 2509 | H23: 第9桌 | I23: 第2桌 | J23: 第2組 | M23: 14 | N23: 09B | O23: 第二車 | P23: 02 | Q23: 07A
A24: 12 | B24: 23 | C24: 王鄆郅 | D24: 富吳通訊處 | E24: 男 | F24: 811 | G24: 2512 | H24: 第9桌 | I24: 第5桌 | J24: 第5組 | M24: 14 | N24: 09A | O24: 第二車 | P24: 02 | Q24: 06F
A25: 12 | B25: 24 | C25: 廖冠傑 | D25: 富吳通訊處 | E25: 男 | F25: 811 | G25: 2512 | H25: 第9桌 | I25: 第3桌 | J25: 第3組 | M25: 14 | N25: 09F | O25: 第二車 | P25: 02 | Q25: 07D
A26: 13 | B26: 25 | C26: 王騌捷 | D26: 富吳通訊處 | E26: 男 | F26: 809 | G26: 2516 | H26: 第8桌 | I26: 第1桌 | J26: 第1組 | M26: 14 | N26: 13A | O26: 第二車 | P26: 02 | Q26: 10B
A27: 13 | B27: 26 | C27: 黃金隆 | D27: 富吳通訊處 | E27: 男 | F27: 809 | G27: 2516 | H27: 第9桌 | I27: 第3桌 | J27: 第3組 | M27: 14 | N27: 10D | O27: 第二車 | P27: 02 | Q27: 08C
A28: 14 | B28: 27 | C28: 呂顏伃 | D28: 富吳通訊處 | E28: 女 | F28: 1108 | G28: 2519 | H28: 第9桌 | I28: 第8桌 | J28: 第8組 | M28: 14 | N28: 10B | O28: 第二車 | P28: 02 | Q28: 08A
A29: 14 | B29: 28 | C29: 陳怡諳 | D29: 富吳通訊處 | E29: 女 | F29: 1108 | G29: 2519 | H29: 第9桌 | I29: 第8桌 | J29: 第8組 | M29: 14 | N29: 09C | O29: 第二車 | P29: 02 | Q29: 07B
... A41: 20 | B41: 40 | C41: 侯宏詣 | D41: 富則通訊處 | E41: 男 | F41: 916 | G41: 2531 | H41: 第8桌 | I41: 第2桌 | J41: 第2組 | M41: 14 | N41: 12D | O41: 第二車 | P41: 02 | Q41: 03F
A42: 21 | B42: 41 | C42: 簡宏鈞 | D42: 富能通訊處 | E42: 男 | F42: 611 | G42: 2605 | H42: 第3桌 | I42: 主桌 | M42: 14 | N42: 13B | O42: 第一車 | P42: 02 | Q42: 10C
A43: 21 | B43: 42 | C43: 王昱文 | D43: 富則通訊處 | E43: 男 | F43: 611 | G43: 2605 | H43: 第5桌 | I43: 第9桌 | J43: 第9組 | M43: 14 | N43: 16F | O43: 第二車 | P43: 04 | Q43: 01D
A44: 22 | B44: 43 | C44: 管卓鈞 | D44: 富能通訊處 | E44: 女 | F44: 613 | G44: 2606 | H44: 第4桌 | I44: 第5桌 | J44: 第5組 | M44: 14 | N44: 13C | O44: 第一車 | P44: 02 | Q44: 10D
A45: 22 | B45: 44 | C45: 林桂安 | D45: 富則通訊處 | E45: 女 | F45: 613 | G45: 2606 | H45: 第5桌 | I45: 第3桌 | J45: 第3組 | M45: 14 | N45: 15B | O45: 第一車 | P45: 02 | Q45: 12A
A46: 23 | B46: 45 | C46: 簡姵萱 | D46: 富能通訊處 | E46: 女 | F46: 618 | G46: 2607 | H46: 第4桌 | I46: 第7桌 | J46: 第7組 | M46: 14 | N46: 13D | O46: 第一車 | P46: 02 | Q46: 10F
A47: 23 | B47: 46 | C47: 潘韻竹 | D47: 富則通訊處 | E47: 女 | F47: 618 | G47: 2607 | H47: 第4桌 | I47: 第8桌 | J47: 第8組 | M47: 14 | N47: 16D | O47: 第一車 | P47: 04 | Q47: 01C
A48: 26 | B48: 47 | C48: 顏明儀 | D48: 富則通訊處 | E48: 女 | F48: 603 | G48: 2608 | H48: 第4桌 | I48: 第2桌 | J48: 第2組 | K48: 組長 | M48: 14 | N48: 15F | O48: 第一車 | P48: 02 | Q48: 13A
A49: 26 | B49: 48 | C49: 王思嵐 | D49: 富則通訊處 | E49: 女 | F49: 603 | G49: 2608 | H49: 第4桌 | I49: 第8桌 | J49: 第8組 | M49: 14 | N49: 03C | O49: 第一車 | P49: 02 | Q49: 13B
A50: 25 | B50: 49 | C50: 鍾怡婷 | D50: 富占通訊處 | E50: 女 | F50: 1015 | G50: 2609 | H50: 第3桌 | I50: 第6桌 | J50: 第6組 | M50: 14 | N50: 08D | O50: 第一車 | P50: 02 | Q50: 06C
A51: 25 | B51: 50 | C51: 林宜潔 | D51: 富占通訊處 | E51: 女 | F51: 1015 | G51: 2609 | H51: 第3桌 | I51: 第9桌 | J51: 第9組 | M51: 14 | N51: 08F | O51: 第一車 | P51: 02 | Q51: 06D
...

Sheet 房間
A1: 房號 | B1: 編號 | C1: 姓名 | D1: 單位 | E1: 性別 | F1: 青島房號 | G1: 濟南房號 | H1: 室友 | I1: 用餐桌次 | J1: 遊覽車次
A2: =總表!A36 | B2: =總表!B36 | C2: =總表!C36 | D2: =總表!D36 | E2: =總表!E36 | F2: =總表!F36 | G2: =總表!G36 | H2: 謝宇軒 | I2: =總表!H36 | J2: =總表!O36
A3: =總表!A37 | B3: =總表!B37 | C3: =總表!C37 | D3: =總表!D37 | E3: =總表!E37 | F3: =總表!F37 | G3: =總表!G37 | H3: 鄭丞哲 | I3: =總表!H37 | J3: =總表!O37
A4: =總表!A32 | B4: =總表!B32 | C4: =總表!C32 | D4: =總表!D32 | E4: =總表!E32 | F4: =總表!F32 | G4: =總表!G32 | H4: 林建璋 | I4: =總表!H32 | J4: =總表!O32
A5: =總表!A33 | B5: =總表!B33 | C5: =總表!C33 | D5: =總表!D33 | E5: =總表!E33 | F5: =總表!F33 | G5: =總表!G33 | H5: 周易慶 | I5: =總表!H33 | J5: =總表!O33
A6: =總表!A82 | B6: =總表!B82 | C6: =總表!C82 | D6: =總表!D82 | E6: =總表!E82 | F6: =總表!F82 | G6: =總表!G82 | H6: 孫振文 | I6: =總表!H82 | J6: =總表!O82
A7: =總表!A83 | B7: =總表!B83 | C7: =總表!C83 | D7: =總表!D83 | E7: =總表!E83 | F7: =總表!F83 | G7: =總表!G83 | H7: 鄭占禮 | I7: =總表!H83 | J7: =總表!O83
A8: =總表!A50 | B8: =總表!B50 | C8: =總表!C50 | D8: =總表!D50 | E8: =總表!E50 | F8: =總表!F50 | G8: =總表!G50 | H8: 林宜潔 | I8: =總表!H50 | J8: =總表!O50
A9: =總表!A51 | B9: =總表!B51 | C9: =總表!C51 | D9: =總表!D51 | E9: =總表!E51 | F9: =總表!F51 | G9: =總表!G51 | H9: 鍾怡婷 | I9: =總表!H51 | J9: =總表!O51
A10: =總表!A60 | B10: =總表!B60 | C10: =總表!C60 | D10: =總表!D60 | E10: =總表!E60 | F10: =總表!F60 | G10: =總表!G60 | H10: 黃馨葦 | I10: =總表!H60 | J10: =總表!O60
A11: =總表!A61 | B11: =總表!B61 | C11: =總表!C61 | D11: =總表!D61 | E11: =總表!E61 | F11: =總表!F61 | G11: =總表!G61 | H11: 李孟珊 | I11: =總表!H61 | J11: =總表!O61
A12: =總表!A72 | B12: =總表!B72 | C12: =總表!C72 | D12: =總表!D72 | E12: =總表!E72 | F12: =總表!F72 | G12: =總表!G72 | H12: 林宏威 | I12: =總表!H72 | J12: =總表!O72
A13: =總表!A73 | B13: =總表!B73 | C13: =總表!C73 | D13: =總表!D73 | E13: =總表!E73 | F13: =總表!F73 | G13: =總表!G73 | H13: 馬英傑 | I13: =總表!H73 | J13: =總表!O73
A14: =總表!A28 | B14: =總表!B28 | C14: =總表!C28 | D14: =總表!D28 | E14: =總表!E28 | F14: =總表!F28 | G14: =總表!G28 | H14: 陳怡諳 | I14: =總表!H28 | J14: =總表!O28
A15: =總表!A29 | B15: =總表!B29 | C15: =總表!C29 | D15: =總表!D29 | E15: =總表!E29 | F15: =總表!F29 | G15: =總表!G29 | H15: 呂顏伃 | I15: =總表!H29 | J15: =總表!O29
A16: =總表!A62 | B16: =總表!B62 | C16: =總表!C62 | D16: =總表!D62 | E16: =總表!E62 | F16: =總表!F62 | G16: =總表!G62 | H16: 張國興 | I16: =總表!H62 | J16: =總表!O62
A17: =總表!A63 | B17: =總表!B63 | C17: =總表!C63 | D17: =總表!D63 | E17: =總表!E63 | F17: =總表!F63 | G17: =總表!G63 | H17: 蔡承遠 | I17: =總表!H63 | J17: =總表!O63
A18: =總表!A16 | B18: =總表!B16 | C18: =總表!C16 | D18: =總表!D16 | E18: =總表!E16 | F18: =總表!F16 | G18: =總表!G16 | H18: 宋里安 | I18: =總表!H16 | J18: =總表!O16
A19: =總表!A17 | B19: =總表!B17 | C19: =總表!C17 | D19: =總表!D17 | E19: =總表!E17 | F19: =總表!F17 | G19: =總表!G17 | H19: 陳昶聿 | I19: =總表!H17 | J19: =總表!O17
A20: =總表!A76 | B20: =總表!B76 | C20: =總表!C76 | D20: =總表!D76 | E20: =總表!E76 | F20: =總表!F76 | G20: =總表!G76 | H20: 葉金玲 | I20: =總表!H76 | J20: =總表!O76
A21: =總表!A77 | B21: =總表!B77 | C21: =總表!C77 | D21: =總表!D77 | E21: =總表!E77 | F21: =總表!F77 | G21: =總表!G77 | H21: 陳龍生 | I21: =總表!H77 | J21: =總表!O77
A22: =總表!A14 | B22: =總表!B14 | C22: =總表!C14 | D22: =總表!D14 | E22: =總表!E14 | F22: =總表!F14 | G22: =總表!G14 | H22: 陳尚禾 | I22: =總表!H14 | J22: =總表!O14
A23: =總表!A15 | B23: =總表!B15 | C23: =總表!C15 | D23: =總表!D15 | E23: =總表!E15 | F23: =總表!F15 | G23: =總表!G15 | H23: 陳武均 | I23: =總表!H15 | J23: =總表!O15
A24: =總表!A74 | B24: =總表!B74 | C24: =總表!C74 | D24: =總表!D74 | E24: =總表!E74 | F24: =總表!F74 | G24: =總表!G74 | H24: 廖家慧 | I24: =總表!H74 | J24: =總表!O74
A25: =總表!A75 | B25: =總表!B75 | C25: =總表!C75 | D25: =總表!D75 | E25: =總表!E75 | F25: =總表!F75 | G25: =總表!G75 | H25: 陳怡萍 | I25: =總表!H75 | J25: =總表!O75
A26: =總表!A8 | B26: =總表!B8 | C26: =總表!C8 | D26: =總表!D8 | E26: =總表!E8 | F26: =總表!F8 | G26: =總表!G8 | H26: 詹政杰 | I26: =總表!H8 | J26: =總表!O8
A27: =總表!A9 | B27: =總表!B9 | C27: =總表!C9 | D27: =總表!D9 | E27: =總表!E9 | F27: =總表!F9 | G27: =總表!G9 | H27: 戴東志 | I27: =總表!H9 | J27: =總表!O9
A28: =總表!A38 | B28: =總表!B38 | C28: =總表!C38 | D28: =總表!D38 | E28: =總表!E38 | F28: =總表!F38 | G28: =總表!G38 | H28: 徐瀚 | I28: =總表!H38 | J28: =總表!O38
A29: =總表!A39 | B29: =總表!B39 | C29: =總表!C39 | D29: =總表!D39 | E29: =總表!E39 | F29: =總表!F39 | G29: =總表!G39 | H29: 戴孜安 | I29: =總表!H39 | J29: =總表!O39
A30: =總表!A48 | B30: =總表!B48 | C30: =總表!C48 | D30: =總表!D48 | E30: =總表!E48 | F30: =總表!F48 | G30: =總表!G48 | H30: 王思嵐 | I30: =總表!H48 | J30: =總表!O48
A31: =總表!A49 | B31: =總表!B49 | C31: =總表!C49 | D31: =總表!D49 | E31: =總表!E49 | F31: =總表!F49 | G31: =總表!G49 | H31: 顏明儀 | I31: =總表!H49 | J31: =總表!O49
A32: =總表!A84 | B32: =總表!B84 | C32: =總表!C84 | D32: =總表!D84 | E32: =總表!E84 | F32: =總表!F84 | G32: =總表!G84 | H32: 單人房 | I32: =總表!H84 | J32: =總表!O84
A33: =總表!A52 | B33: =總表!B52 | C33: =總表!C52 | D33: =總表!D52 | E33: =總表!E52 | F33: =總表!F52 | G33: =總表!G52 | H33: 徐維鈴 | I33: =總表!H52 | J33: =總表!O52
A34: =總表!A53 | B34: =總表!B53 | C34: =總表!C53 | D34: =總表!D53 | E34: =總表!E53 | F34: =總表!F53 | G34: =總表!G53 | H34: 傅佳旻 | I34: =總表!H53 | J34: =總表!O53
A35: =總表!A64 | B35: =總表!B64 | C35: =總表!C64 | D35: =總表!D64 | E35: =總表!E64 | F35: =總表!F64 | G35: =總表!G64 | H35: 王銘宏 | I35: =總表!H64 | J35: =總表!O64
A36: =總表!A65 | B36: =總表!B65 | C36: =總表!C65 | D36: =總表!D65 | E36: =總表!E65 | F36: =總表!F65 | G36: =總表!G65 | H36: 高智源 | I36: =總表!H65 | J36: =總表!O65
A37: =總表!A42 | B37: =總表!B42 | C37: =總表!C42 | D37: =總表!D42 | E37: =總表!E42 | F37: =總表!F42 | G37: =總表!G42 | H37: 王昱文 | I37: =總表!H42 | J37: =總表!O42
A38: =總表!A43 | B38: =總表!B43 | C38: =總表!C43 | D38: =總表!D43 | E38: =總表!E43 | F38: =總表!F43 | G38: =總表!G43 | H38: 簡宏鈞 | I38: =總表!H43 | J38: =總表!O43
A39: =總表!A44 | B39: =總表!B44 | C39: =總表!C44 | D39: =總表!D44 | E39: =總表!E44 | F39: =總表!F44 | G39: =總表!G44 | H39: 林桂安 | I39: =總表!H44 | J39: =總表!O44
A40: =總表!A45 | B40: =總表!B45 | C40: =總表!C45 | D40: =總表!D45 | E40: =總表!E45 | F40: =總表!F45 | G40: =總表!G45 | H40: 管卓鈞 | I40: =總表!H45 | J40: =總表!O45
...

Sheet 桌次
A1: 桌次 | B1: 姓名 | C1: 單位 | D1: 性別 | E1: 房號 | F1: 編號 | G1: 青島房號 | H1: 濟南房號 | I1: 遊覽車次
A2: =總表!H2 | B2: =總表!C2 | C2: =總表!D2 | D2: =總表!E2 | E2: =總表!A2 | F2: =總表!B2 | G2: =總表!F2 | H2: =總表!G2 | I2: =總表!O2
A3: =總表!H3 | B3: =總表!C3 | C3: =總表!D3 | D3: =總表!E3 | E3: =總表!A3 | F3: =總表!B3 | G3: =總表!F3 | H3: =總表!G3 | I3: =總表!O3
A4: =總表!H4 | B4: =總表!C4 | C4: =總表!D4 | D4: =總表!E4 | E4: =總表!A4 | F4: =總表!B4 | G4: =總表!F4 | H4: =總表!G4 | I4: =總表!O4
A5: =總表!H5 | B5: =總表!C5 | C5: =總表!D5 | D5: =總表!E5 | E5: =總表!A5 | F5: =總表!B5 | G5: =總表!F5 | H5: =總表!G5 | I5: =總表!O5
A6: =總表!H6 | B6: =總表!C6 | C6: =總表!D6 | D6: =總表!E6 | E6: =總表!A6 | F6: =總表!B6 | G6: =總表!F6 | H6: =總表!G6 | I6: =總表!O6
A7: =總表!H7 | B7: =總表!C7 | C7: =總表!D7 | D7: =總表!E7 | E7: =總表!A7 | F7: =總表!B7 | G7: =總表!F7 | H7: =總表!G7 | I7: =總表!O7
A8: =總表!H8 | B8: =總表!C8 | C8: =總表!D8 | D8: =總表!E8 | E8: =總表!A8 | F8: =總表!B8 | G8: =總表!F8 | H8: =總表!G8 | I8: =總表!O8
A9: =總表!H9 | B9: =總表!C9 | C9: =總表!D9 | D9: =總表!E9 | E9: =總表!A9 | F9: =總表!B9 | G9: =總表!F9 | H9: =總表!G9 | I9: =總表!O9
A10: =總表!H10 | B10: =總表!C10 | C10: =總表!D10 | D10: =總表!E10 | E10: =總表!A10 | F10: =總表!B10 | G10: =總表!F10 | H10: =總表!G10 | I10: =總表!O10
A11: =總表!H11 | B11: =總表!C11 | C11: =總表!D11 | D11: =總表!E11 | E11: =總表!A11 | F11: =總表!B11 | G11: =總表!F11 | H11: =總表!G11 | I11: =總表!O11
A12: =總表!H12 | B12: =總表!C12 | C12: =總表!D12 | D12: =總表!E12 | E12: =總表!A12 | F12: =總表!B12 | G12: =總表!F12 | H12: =總表!G12 | I12: =總表!O12
A13: =總表!H13 | B13: =總表!C13 | C13: =總表!D13 | D13: =總表!E13 | E13: =總表!A13 | F13: =總表!B13 | G13: =總表!F13 | H13: =總表!G13 | I13: =總表!O13
A14: =總表!H68 | B14: =總表!C68 | C14: =總表!D68 | D14: =總表!E68 | E14: =總表!A68 | F14: =總表!B68 | G14: =總表!F68 | H14: =總表!G68 | I14: =總表!O68
A15: =總表!H69 | B15: =總表!C69 | C15: =總表!D69 | D15: =總表!E69 | E15: =總表!A69 | F15: =總表!B69 | G15: =總表!F69 | H15: =總表!G69 | I15: =總表!O69
A16: =總表!H70 | B16: =總表!C70 | C16: =總表!D70 | D16: =總表!E70 | E16: =總表!A70 | F16: =總表!B70 | G16: =總表!F70 | H16: =總表!G70 | I16: =總表!O70
A17: =總表!H71 | B17: =總表!C71 | C17: =總表!D71 | D17: =總表!E71 | E17: =總表!A71 | F17: =總表!B71 | G17: =總表!F71 | H17: =總表!G71 | I17: =總表!O71
A18: =總表!H72 | B18: =總表!C72 | C18: =總表!D72 | D18: =總表!E72 | E18: =總表!A72 | F18: =總表!B72 | G18: =總表!F72 | H18: =總表!G72 | I18: =總表!O72
A19: =總表!H73 | B19: =總表!C73 | C19: =總表!D73 | D19: =總表!E73 | E19: =總表!A73 | F19: =總表!B73 | G19: =總表!F73 | H19: =總表!G73 | I19: =總表!O73
A20: =總表!H74 | B20: =總表!C74 | C20: =總表!D74 | D20: =總表!E74 | E20: =總表!A74 | F20: =總表!B74 | G20: =總表!F74 | H20: =總表!G74 | I20: =總表!O74
A21: =總表!H75 | B21: =總表!C75 | C21: =總表!D75 | D21: =總表!E75 | E21: =總表!A75 | F21: =總表!B75 | G21: =總表!F75 | H21: =總表!G75 | I21: =總表!O75
A22: =總表!H42 | B22: =總表!C42 | C22: =總表!D42 | D22: =總表!E42 | E22: =總表!A42 | F22: =總表!B42 | G22: =總表!F42 | H22: =總表!G42 | I22: =總表!O42
A23: =總表!H50 | B23: =總表!C50 | C23: =總表!D50 | D23: =總表!E50 | E23: =總表!A50 | F23: =總表!B50 | G23: =總表!F50 | H23: =總表!G50 | I23: =總表!O50
A24: =總表!H51 | B24: =總表!C51 | C24: =總表!D51 | D24: =總表!E51 | E24: =總表!A51 | F24: =總表!B51 | G24: =總表!F51 | H24: =總表!G51 | I24: =總表!O51
A25: =總表!H52 | B25: =總表!C52 | C25: =總表!D52 | D25: =總表!E52 | E25: =總表!A52 | F25: =總表!B52 | G25: =總表!F52 | H25: =總表!G52 | I25: =總表!O52
A26: =總表!H53 | B26: =總表!C53 | C26: =總表!D53 | D26: =總表!E53 | E26: =總表!A53 | F26: =總表!B53 | G26: =總表!F53 | H26: =總表!G53 | I26: =總表!O53
A27: =總表!H62 | B27: =總表!C62 | C27: =總表!D62 | D27: =總表!E62 | E27: =總表!A62 | F27: =總表!B62 | G27: =總表!F62 | H27: =總表!G62 | I27: =總表!O62
A28: =總表!H63 | B28: =總表!C63 | C28: =總表!D63 | D28: =總表!E63 | E28: =總表!A63 | F28: =總表!B63 | G28: =總表!F63 | H28: =總表!G63 | I28: =總表!O63
A29: =總表!H82 | B29: =總表!C82 | C29: =總表!D82 | D29: =總表!E82 | E29: =總表!A82 | F29: =總表!B82 | G29: =總表!F82 | H29: =總表!G82 | I29: =總表!O82
A30: =總表!H83 | B30: =總表!C83 | C30: =總表!D83 | D30: =總表!E83 | E30: =總表!A83 | F30: =總表!B83 | G30: =總表!F83 | H30: =總表!G83 | I30: =總表!O83
A31: =總表!H84 | B31: =總表!C84 | C31: =總表!D84 | D31: =總表!E84 | E31: =總表!A84 | F31: =總表!B84 | G31: =總表!F84 | H31: =總表!G84 | I31: =總表!O84
A32: =總表!H44 | B32: =總表!C44 | C32: =總表!D44 | D32: =總表!E44 | E32: =總表!A44 | F32: =總表!B44 | G32: =總表!F44 | H32: =總表!G44 | I32: =總表!O44
A33: =總表!H46 | B33: =總表!C46 | C33: =總表!D46 | D33: =總表!E46 | E33: =總表!A46 | F33: =總表!B46 | G33: =總表!F46 | H33: =總表!G46 | I33: =總表!O46
A34: =總表!H47 | B34: =總表!C47 | C34: =總表!D47 | D34: =總表!E47 | E34: =總表!A47 | F34: =總表!B47 | G34: =總表!F47 | H34: =總表!G47 | I34: =總表!O47
A35: =總表!H48 | B35: =總表!C48 | C35: =總表!D48 | D35: =總表!E48 | E35: =總表!A48 | F35: =總表!B48 | G35: =總表!F48 | H35: =總表!G48 | I35: =總表!O48
A36: =總表!H49 | B36: =總表!C49 | C36: =總表!D49 | D36: =總表!E49 | E36: =總表!A49 | F36: =總表!B49 | G36: =總表!F49 | H36: =總表!G49 | I36: =總表!O49
A37: =總表!H56 | B37: =總表!C56 | C37: =總表!D56 | D37: =總表!E56 | E37: =總表!A56 | F37: =總表!B56 | G37: =總表!F56 | H37: =總表!G56 | I37: =總表!O56
A38: =總表!H57 | B38: =總表!C57 | C38: =總表!D57 | D38: =總表!E57 | E38: =總表!A57 | F38: =總表!B57 | G38: =總表!F57 | H38: =總表!G57 | I38: =總表!O57
A39: =總表!H65 | B39: =總表!C65 | C39: =總表!D65 | D39: =總表!E65 | E39: =總表!A65 | F39: =總表!B65 | G39: =總表!F65 | H39: =總表!G65 | I39: =總表!O65
A40: =總表!H80 | B40: =總表!C80 | C40: =總表!D80 | D40: =總表!E80 | E40: =總表!A80 | F40: =總表!B80 | G40: =總表!F80 | H40: =總表!G80 | I40: =總表!O80
...

Sheet 晚宴
A1: 晚宴座位 | B1: 課程分組 | C1: 組長 | D1: 姓名 | E1: 單位 | F1: 性別 | G1: 房號 | H1: 編號 | I1: 備註
A2: =總表!I4 | B2: =總表!J4 | C2: =總表!K4 | D2: =總表!C4 | E2: =總表!D4 | F2: =總表!E4 | G2: =總表!A4 | H2: =總表!B4 | I2: =總表!L4
A3: =總表!I42 | B3: =總表!J42 | C3: =總表!K42 | D3: =總表!C42 | E3: =總表!D42 | F3: =總表!E42 | G3: =總表!A42 | H3: =總表!B42 | I3: =總表!L42
A4: =總表!I81 | B4: =總表!J81 | C4: =總表!K81 | D4: =總表!C81 | E4: =總表!D81 | F4: =總表!E81 | G4: =總表!A81 | H4: =總表!B81 | I4: =總表!L81
A5: =總表!I82 | B5: =總表!J82 | C5: =總表!K82 | D5: =總表!C82 | E5: =總表!D82 | F5: =總表!E82 | G5: =總表!A82 | H5: =總表!B82 | I5: =總表!L82
A6: =總表!I83 | B6: =總表!J83 | C6: =總表!K83 | D6: =總表!C83 | E6: =總表!D83 | F6: =總表!E83 | G6: =總表!A83 | H6: =總表!B83 | I6: =總表!L83
A7: =總表!I86 | B7: =總表!J86 | C7: =總表!K86 | D7: =總表!C86 | E7: =總表!D86 | F7: =總表!E86 | G7: =總表!A86 | H7: =總表!B86 | I7: =總表!L86
A8: =總表!I8 | B8: =總表!J8 | C8: =總表!K8 | D8: =總表!C8 | E8: =總表!D8 | F8: =總表!E8 | G8: =總表!A8 | H8: =總表!B8 | I8: =總表!L8
A9: =總表!I12 | B9: =總表!J12 | C9: =總表!K12 | D9: =總表!C12 | E9: =總表!D12 | F9: =總表!E12 | G9: =總表!A12 | H9: =總表!B12 | I9: =總表!L12
A10: =總表!I26 | B10: =總表!J26 | C10: =總表!K26 | D10: =總表!C26 | E10: =總表!D26 | F10: =總表!E26 | G10: =總表!A26 | H10: =總表!B26 | I10: =總表!L26
A11: =總表!I36 | B11: =總表!J36 | C11: =總表!K36 | D11: =總表!C36 | E11: =總表!D36 | F11: =總表!E36 | G11: =總表!A36 | H11: =總表!B36 | I11: =總表!L36
A12: =總表!I53 | B12: =總表!J53 | C12: =總表!K53 | D12: =總表!C53 | E12: =總表!D53 | F12: =總表!E53 | G12: =總表!A53 | H12: =總表!B53 | I12: =總表!L53
A13: =總表!I56 | B13: =總表!J56 | C13: =總表!K56 | D13: =總表!C56 | E13: =總表!D56 | F13: =總表!E56 | G13: =總表!A56 | H13: =總表!B56 | I13: =總表!L56
A14: =總表!I59 | B14: =總表!J59 | C14: =總表!K59 | D14: =總表!C59 | E14: =總表!D59 | F14: =總表!E59 | G14: =總表!A59 | H14: =總表!B59 | I14: =總表!L59
A15: =總表!I70 | B15: =總表!J70 | C15: =總表!K70 | D15: =總表!C70 | E15: =總表!D70 | F15: =總表!E70 | G15: =總表!A70 | H15: =總表!B70 | I15: =總表!L70
A16: =總表!I77 | B16: =總表!J77 | C16: =總表!K77 | D16: =總表!C77 | E16: =總表!D77 | F16: =總表!E77 | G16: =總表!A77 | H16: =總表!B77 | I16: =總表!L77
A17: =總表!I5 | B17: =總表!J5 | C17: =總表!K5 | D17: =總表!C5 | E17: =總表!D5 | F17: =總表!E5 | G17: =總表!A5 | H17: =總表!B5 | I17: =總表!L5
A18: =總表!I13 | B18: =總表!J13 | C18: =總表!K13 | D18: =總表!C13 | E18: =總表!D13 | F18: =總表!E13 | G18: =總表!A13 | H18: =總表!B13 | I18: =總表!L13
A19: =總表!I18 | B19: =總表!J18 | C19: =總表!K18 | D19: =總表!C18 | E19: =總表!D18 | F19: =總表!E18 | G19: =總表!A18 | H19: =總表!B18 | I19: =總表!L18
A20: =總表!I21 | B20: =總表!J21 | C20: =總表!K21 | D20: =總表!C21 | E20: =總表!D21 | F20: =總表!E21 | G20: =總表!A21 | H20: =總表!B21 | I20: =總表!L21
A21: =總表!I23 | B21: =總表!J23 | C21: =總表!K23 | D21: =總表!C23 | E21: =總表!D23 | F21: =總表!E23 | G21: =總表!A23 | H21: =總表!B23 | I21: =總表!L23
A22: =總表!I41 | B22: =總表!J41 | C22: =總表!K41 | D22: =總表!C41 | E22: =總表!D41 | F22: =總表!E41 | G22: =總表!A41 | H22: =總表!B41 | I22: =總表!L41
A23: =總表!I48 | B23: =總表!J48 | C23: =總表!K48 | D23: =總表!C48 | E23: =總表!D48 | F23: =總表!E48 | G23: =總表!A48 | H23: =總表!B48 | I23: =總表!L48
A24: =總表!I64 | B24: =總表!J64 | C24: =總表!K64 | D24: =總表!C64 | E24: =總表!D64 | F24: =總表!E64 | G24: =總表!A64 | H24: =總表!B64 | I24: =總表!L64
A25: =總表!I79 | B25: =總表!J79 | C25: =總表!K79 | D25: =總表!C79 | E25: =總表!D79 | F25: =總表!E79 | G25: =總表!A79 | H25: =總表!B79 | I25: =總表!L79
A26: =總表!I6 | B26: =總表!J6 | C26: =總表!K6 | D26: =總表!C6 | E26: =總表!D6 | F26: =總表!E6 | G26: =總表!A6 | H26: =總表!B6 | I26: =總表!L6
A27: =總表!I17 | B27: =總表!J17 | C27: =總表!K17 | D27: =總表!C17 | E27: =總表!D17 | F27: =總表!E17 | G27: =總表!A17 | H27: =總表!B17 | I27: =總表!L17
A28: =總表!I25 | B28: =總表!J25 | C28: =總表!K25 | D28: =總表!C25 | E28: =總表!D25 | F28: =總表!E25 | G28: =總表!A25 | H28: =總表!B25 | I28: =總表!L25
A29: =總表!I27 | B29: =總表!J27 | C29: =總表!K27 | D29: =總表!C27 | E29: =總表!D27 | F29: =總表!E27 | G29: =總表!A27 | H29: =總表!B27 | I29: =總表!L27
A30: =總表!I31 | B30: =總表!J31 | C30: =總表!K31 | D30: =總表!C31 | E30: =總表!D31 | F30: =總表!E31 | G30: =總表!A31 | H30: =總表!B31 | I30: =總表!L31
A31: =總表!I35 | B31: =總表!J35 | C31: =總表!K35 | D31: =總表!C35 | E31: =總表!D35 | F31: =總表!E35 | G31: =總表!A35 | H31: =總表!B35 | I31: =總表!L35
A32: =總表!I45 | B32: =總表!J45 | C32: =總表!K45 | D32: =總表!C45 | E32: =總表!D45 | F32: =總表!E45 | G32: =總表!A45 | H32: =總表!B45 | I32: =總表!L45
A33: =總表!I65 | B33: =總表!J65 | C33: =總表!K65 | D33: =總表!C65 | E33: =總表!D65 | F33: =總表!E65 | G33: =總表!A65 | H33: =總表!B65 | I33: =總表!L65
A34: =總表!I71 | B34: =總表!J71 | C34: =總表!K71 | D34: =總表!C71 | E34: =總表!D71 | F34: =總表!E71 | G34: =總表!A71 | H34: =總表!B71 | I34: =總表!L71
A35: =總表!I19 | B35: =總表!J19 | C35: =總表!K19 | D35: =總表!C19 | E35: =總表!D19 | F35: =總表!E19 | G35: =總表!A19 | H35: =總表!B19 | I35: =總表!L19
A36: =總表!I22 | B36: =總表!J22 | C36: =總表!K22 | D36: =總表!C22 | E36: =總表!D22 | F36: =總表!E22 | G36: =總表!A22 | H36: =總表!B22 | I36: =總表!L22
A37: =總表!I58 | B37: =總表!J58 | C37: =總表!K58 | D37: =總表!C58 | E37: =總表!D58 | F37: =總表!E58 | G37: =總表!A58 | H37: =總表!B58 | I37: =總表!L58
A38: =總表!I63 | B38: =總表!J63 | C38: =總表!K63 | D38: =總表!C63 | E38: =總表!D63 | F38: =總表!E63 | G38: =總表!A63 | H38: =總表!B63 | I38: =總表!L63
A39: =總表!I67 | B39: =總表!J67 | C39: =總表!K67 | D39: =總表!C67 | E39: =總表!D67 | F39: =總表!E67 | G39: =總表!A67 | H39: =總表!B67 | I39: =總表!L67
A40: =總表!I69 | B40: =總表!J69 | C40: =總表!K69 | D40: =總表!C69 | E40: =總表!D69 | F40: =總表!E69 | G40: =總表!A69 | H40: =總表!B69 | I40: =總表!L69
...

Sheet 遊覽車次
A1: 遊覽車次 | B1: 姓名 | C1: 單位 | D1: 性別 | E1: 房號 | F1: 編號 | G1: 用餐桌次 | H1: 晚宴桌次
A2: =總表!O2 | B2: =總表!C2 | C2: =總表!D2 | D2: =總表!E2 | E2: =總表!A2 | F2: =總表!B2 | G2: =總表!H2 | H2: =總表!I2
A3: =總表!O3 | B3: =總表!C3 | C3: =總表!D3 | D3: =總表!E3 | E3: =總表!A3 | F3: =總表!B3 | G3: =總表!H3 | H3: =總表!I3
A4: =總表!O4 | B4: =總表!C4 | C4: =總表!D4 | D4: =總表!E4 | E4: =總表!A4 | F4: =總表!B4 | G4: =總表!H4 | H4: =總表!I4
A5: =總表!O5 | B5: =總表!C5 | C5: =總表!D5 | D5: =總表!E5 | E5: =總表!A5 | F5: =總表!B5 | G5: =總表!H5 | H5: =總表!I5
A6: =總表!O6 | B6: =總表!C6 | C6: =總表!D6 | D6: =總表!E6 | E6: =總表!A6 | F6: =總表!B6 | G6: =總表!H6 | H6: =總表!I6
A7: =總表!O7 | B7: =總表!C7 | C7: =總表!D7 | D7: =總表!E7 | E7: =總表!A7 | F7: =總表!B7 | G7: =總表!H7 | H7: =總表!I7
A8: =總表!O8 | B8: =總表!C8 | C8: =總表!D8 | D8: =總表!E8 | E8: =總表!A8 | F8: =總表!B8 | G8: =總表!H8 | H8: =總表!I8
A9: =總表!O9 | B9: =總表!C9 | C9: =總表!D9 | D9: =總表!E9 | E9: =總表!A9 | F9: =總表!B9 | G9: =總表!H9 | H9: =總表!I9
A10: =總表!O10 | B10: =總表!C10 | C10: =總表!D10 | D10: =總表!E10 | E10: =總表!A10 | F10: =總表!B10 | G10: =總表!H10 | H10: =總表!I10
A11: =總表!O11 | B11: =總表!C11 | C11: =總表!D11 | D11: =總表!E11 | E11: =總表!A11 | F11: =總表!B11 | G11: =總表!H11 | H11: =總表!I11
A12: =總表!O12 | B12: =總表!C12 | C12: =總表!D12 | D12: =總表!E12 | E12: =總表!A12 | F12: =總表!B12 | G12: =總表!H12 | H12: =總表!I12
A13: =總表!O13 | B13: =總表!C13 | C13: =總表!D13 | D13: =總表!E13 | E13: =總表!A13 | F13: =總表!B13 | G13: =總表!H13 | H13: =總表!I13
A14: =總表!O42 | B14: =總表!C42 | C14: =總表!D42 | D14: =總表!E42 | E14: =總表!A42 | F14: =總表!B42 | G14: =總表!H42 | H14: =總表!I42
A15: =總表!O44 | B15: =總表!C44 | C15: =總表!D44 | D15: =總表!E44 | E15: =總表!A44 | F15: =總表!B44 | G15: =總表!H44 | H15: =總表!I44
A16: =總表!O45 | B16: =總表!C45 | C16: =總表!D45 | D16: =總表!E45 | E16: =總表!A45 | F16: =總表!B45 | G16: =總表!H45 | H16: =總表!I45
A17: =總表!O46 | B17: =總表!C46 | C17: =總表!D46 | D17: =總表!E46 | E17: =總表!A46 | F17: =總表!B46 | G17: =總表!H46 | H17: =總表!I46
A18: =總表!O47 | B18: =總表!C47 | C18: =總表!D47 | D18: =總表!E47 | E18: =總表!A47 | F18: =總表!B47 | G18: =總表!H47 | H18: =總表!I47
A19: =總表!O48 | B19: =總表!C48 | C19: =總表!D48 | D19: =總表!E48 | E19: =總表!A48 | F19: =總表!B48 | G19: =總表!H48 | H19: =總表!I48
A20: =總表!O49 | B20: =總表!C49 | C20: =總表!D49 | D20: =總表!E49 | E20: =總表!A49 | F20: =總表!B49 | G20: =總表!H49 | H20: =總表!I49
A21: =總表!O50 | B21: =總表!C50 | C21: =總表!D50 | D21: =總表!E50 | E21: =總表!A50 | F21: =總表!B50 | G21: =總表!H50 | H21: =總表!I50
A22: =總表!O51 | B22: =總表!C51 | C22: =總表!D51 | D22: =總表!E51 | E22: =總表!A51 | F22: =總表!B51 | G22: =總表!H51 | H22: =總表!I51
A23: =總表!O52 | B23: =總表!C52 | C23: =總表!D52 | D23: =總表!E52 | E23: =總表!A52 | F23: =總表!B52 | G23: =總表!H52 | H23: =總表!I52
A24: =總表!O53 | B24: =總表!C53 | C24: =總表!D53 | D24: =總表!E53 | E24: =總表!A53 | F24: =總表!B53 | G24: =總表!H53 | H24: =總表!I53
A25: =總表!O56 | B25: =總表!C56 | C25: =總表!D56 | D25: =總表!E56 | E25: =總表!A56 | F25: =總表!B56 | G25: =總表!H56 | H25: =總表!I56
A26: =總表!O57 | B26: =總表!C57 | C26: =總表!D57 | D26: =總表!E57 | E26: =總表!A57 | F26: =總表!B57 | G26: =總表!H57 | H26: =總表!I57
A27: =總表!O61 | B27: =總表!C61 | C27: =總表!D61 | D27: =總表!E61 | E27: =總表!A61 | F27: =總表!B61 | G27: =總表!H61 | H27: =總表!I61
A28: =總表!O62 | B28: =總表!C62 | C28: =總表!D62 | D28: =總表!E62 | E28: =總表!A62 | F28: =總表!B62 | G28: =總表!H62 | H28: =總表!I62
A29: =總表!O63 | B29: =總表!C63 | C29: =總表!D63 | D29: =總表!E63 | E29: =總表!A63 | F29: =總表!B63 | G29: =總表!H63 | H29: =總表!I63
A30: =總表!O65 | B30: =總表!C65 | C30: =總表!D65 | D30: =總表!E65 | E30: =總表!A65 | F30: =總表!B65 | G30: =總表!H65 | H30: =總表!I65
A31: =總表!O68 | B31: =總表!C68 | C31: =總表!D68 | D31: =總表!E68 | E31: =總表!A68 | F31: =總表!B68 | G31: =總表!H68 | H31: =總表!I68
A32: =總表!O69 | B32: =總表!C69 | C32: =總表!D69 | D32: =總表!E69 | E32: =總表!A69 | F32: =總表!B69 | G32: =總表!H69 | H32: =總表!I69
A33: =總表!O70 | B33: =總表!C70 | C33: =總表!D70 | D33: =總表!E70 | E33: =總表!A70 | F33: =總表!B70 | G33: =總表!H70 | H33: =總表!I70
A34: =總表!O71 | B34: =總表!C71 | C34: =總表!D71 | D34: =總表!E71 | E34: =總表!A71 | F34: =總表!B71 | G34: =總表!H71 | H34: =總表!I71
A35: =總表!O72 | B35: =總表!C72 | C35: =總表!D72 | D35: =總表!E72 | E35: =總表!A72 | F35: =總表!B72 | G35: =總表!H72 | H35: =總表!I72
A36: =總表!O73 | B36: =總表!C73 | C36: =總表!D73 | D36: =總表!E73 | E36: =總表!A73 | F36: =總表!B73 | G36: =總表!H73 | H36: =總表!I73
A37: =總表!O74 | B37: =總表!C74 | C37: =總表!D74 | D37: =總表!E74 | E37: =總表!A74 | F37: =總表!B74 | G37: =總表!H74 | H37: =總表!I74
A38: =總表!O75 | B38: =總表!C75 | C38: =總表!D75 | D38: =總表!E75 | E38: =總表!A75 | F38: =總表!B75 | G38: =總表!H75 | H38: =總表!I75
A39: =總表!O80 | B39: =總表!C80 | C39: =總表!D80 | D39: =總表!E80 | E39: =總表!A80 | F39: =總表!B80 | G39: =總表!H80 | H39: =總表!I80
A40: =總表!O81 | B40: =總表!C81 | C40: =總表!D81 | D40: =總表!E81 | E40: =總表!A81 | F40: =總表!B81 | G40: =總表!H81 | H40: =總表!I81
...

Sheet 高鐵
A1: 方向 | B1: 日期 | C1: 車次 | D1: 路線 | E1: 時間 | F1: 姓名 | G1: 單位 | H1: 車廂 | I1: 座位 | J1: 遊覽車次 | K1: 用餐桌次
A2: 去程 | B2: 2026.07.15（三） | C2: G1074 | D2: 青島 → 濟南 | E2: 14:36–17:20 | F2: =總表!C49 | G2: =總表!D49 | H2: =總表!M49 | I2: =總表!N49 | J2: =總表!O49 | K2: =總表!H49
A3: 去程 | B3: 2026.07.15（三） | C3: G1074 | D3: 青島 → 濟南 | E3: 14:36–17:20 | F3: =總表!C62 | G3: =總表!D62 | H3: =總表!M62 | I3: =總表!N62 | J3: =總表!O62 | K3: =總表!H62
A4: 去程 | B4: 2026.07.15（三） | C4: G1074 | D4: 青島 → 濟南 | E4: 14:36–17:20 | F4: =總表!C59 | G4: =總表!D59 | H4: =總表!M59 | I4: =總表!N59 | J4: =總表!O59 | K4: =總表!H59
A5: 去程 | B5: 2026.07.15（三） | C5: G1074 | D5: 青島 → 濟南 | E5: 14:36–17:20 | F5: =總表!C8 | G5: =總表!D8 | H5: =總表!M8 | I5: =總表!N8 | J5: =總表!O8 | K5: =總表!H8
A6: 去程 | B6: 2026.07.15（三） | C6: G1074 | D6: 青島 → 濟南 | E6: 14:36–17:20 | F6: =總表!C4 | G6: =總表!D4 | H6: =總表!M4 | I6: =總表!N4 | J6: =總表!O4 | K6: =總表!H4
A7: 去程 | B7: 2026.07.15（三） | C7: G1074 | D7: 青島 → 濟南 | E7: 14:36–17:20 | F7: =總表!C3 | G7: =總表!D3 | H7: =總表!M3 | I7: =總表!N3 | J7: =總表!O3 | K7: =總表!H3
A8: 去程 | B8: 2026.07.15（三） | C8: G1074 | D8: 青島 → 濟南 | E8: 14:36–17:20 | F8: =總表!C2 | G8: =總表!D2 | H8: =總表!M2 | I8: =總表!N2 | J8: =總表!O2 | K8: =總表!H2
A9: 去程 | B9: 2026.07.15（三） | C9: G1074 | D9: 青島 → 濟南 | E9: 14:36–17:20 | F9: =總表!C6 | G9: =總表!D6 | H9: =總表!M6 | I9: =總表!N6 | J9: =總表!O6 | K9: =總表!H6
A10: 去程 | B10: 2026.07.15（三） | C10: G1074 | D10: 青島 → 濟南 | E10: 14:36–17:20 | F10: =總表!C9 | G10: =總表!D9 | H10: =總表!M9 | I10: =總表!N9 | J10: =總表!O9 | K10: =總表!H9
A11: 去程 | B11: 2026.07.15（三） | C11: G1074 | D11: 青島 → 濟南 | E11: 14:36–17:20 | F11: =總表!C7 | G11: =總表!D7 | H11: =總表!M7 | I11: =總表!N7 | J11: =總表!O7 | K11: =總表!H7
A12: 去程 | B12: 2026.07.15（三） | C12: G1074 | D12: 青島 → 濟南 | E12: 14:36–17:20 | F12: =總表!C5 | G12: =總表!D5 | H12: =總表!M5 | I12: =總表!N5 | J12: =總表!O5 | K12: =總表!H5
A13: 去程 | B13: 2026.07.15（三） | C13: G1074 | D13: 青島 → 濟南 | E13: 14:36–17:20 | F13: =總表!C10 | G13: =總表!D10 | H13: =總表!M10 | I13: =總表!N10 | J13: =總表!O10 | K13: =總表!H10
A14: 去程 | B14: 2026.07.15（三） | C14: G1074 | D14: 青島 → 濟南 | E14: 14:36–17:20 | F14: =總表!C11 | G14: =總表!D11 | H14: =總表!M11 | I14: =總表!N11 | J14: =總表!O11 | K14: =總表!H11
A15: 去程 | B15: 2026.07.15（三） | C15: G1074 | D15: 青島 → 濟南 | E15: 14:36–17:20 | F15: =總表!C12 | G15: =總表!D12 | H15: =總表!M12 | I15: =總表!N12 | J15: =總表!O12 | K15: =總表!H12
A16: 去程 | B16: 2026.07.15（三） | C16: G1074 | D16: 青島 → 濟南 | E16: 14:36–17:20 | F16: =總表!C13 | G16: =總表!D13 | H16: =總表!M13 | I16: =總表!N13 | J16: =總表!O13 | K16: =總表!H13
A17: 去程 | B17: 2026.07.15（三） | C17: G1074 | D17: 青島 → 濟南 | E17: 14:36–17:20 | F17: =總表!C14 | G17: =總表!D14 | H17: =總表!M14 | I17: =總表!N14 | J17: =總表!O14 | K17: =總表!H14
A18: 去程 | B18: 2026.07.15（三） | C18: G1074 | D18: 青島 → 濟南 | E18: 14:36–17:20 | F18: =總表!C15 | G18: =總表!D15 | H18: =總表!M15 | I18: =總表!N15 | J18: =總表!O15 | K18: =總表!H15
A19: 去程 | B19: 2026.07.15（三） | C19: G1074 | D19: 青島 → 濟南 | E19: 14:36–17:20 | F19: =總表!C18 | G19: =總表!D18 | H19: =總表!M18 | I19: =總表!N18 | J19: =總表!O18 | K19: =總表!H18
A20: 去程 | B20: 2026.07.15（三） | C20: G1074 | D20: 青島 → 濟南 | E20: 14:36–17:20 | F20: =總表!C16 | G20: =總表!D16 | H20: =總表!M16 | I20: =總表!N16 | J20: =總表!O16 | K20: =總表!H16
A21: 去程 | B21: 2026.07.15（三） | C21: G1074 | D21: 青島 → 濟南 | E21: 14:36–17:20 | F21: =總表!C20 | G21: =總表!D20 | H21: =總表!M20 | I21: =總表!N20 | J21: =總表!O20 | K21: =總表!H20
A22: 去程 | B22: 2026.07.15（三） | C22: G1074 | D22: 青島 → 濟南 | E22: 14:36–17:20 | F22: =總表!C17 | G22: =總表!D17 | H22: =總表!M17 | I22: =總表!N17 | J22: =總表!O17 | K22: =總表!H17
A23: 去程 | B23: 2026.07.15（三） | C23: G1074 | D23: 青島 → 濟南 | E23: 14:36–17:20 | F23: =總表!C19 | G23: =總表!D19 | H23: =總表!M19 | I23: =總表!N19 | J23: =總表!O19 | K23: =總表!H19
A24: 去程 | B24: 2026.07.15（三） | C24: G1074 | D24: 青島 → 濟南 | E24: 14:36–17:20 | F24: =總表!C52 | G24: =總表!D52 | H24: =總表!M52 | I24: =總表!N52 | J24: =總表!O52 | K24: =總表!H52
A25: 去程 | B25: 2026.07.15（三） | C25: G1074 | D25: 青島 → 濟南 | E25: 14:36–17:20 | F25: =總表!C53 | G25: =總表!D53 | H25: =總表!M53 | I25: =總表!N53 | J25: =總表!O53 | K25: =總表!H53
A26: 去程 | B26: 2026.07.15（三） | C26: G1074 | D26: 青島 → 濟南 | E26: 14:36–17:20 | F26: =總表!C84 | G26: =總表!D84 | H26: =總表!M84 | I26: =總表!N84 | J26: =總表!O84 | K26: =總表!H84
A27: 去程 | B27: 2026.07.15（三） | C27: G1074 | D27: 青島 → 濟南 | E27: 14:36–17:20 | F27: =總表!C82 | G27: =總表!D82 | H27: =總表!M82 | I27: =總表!N82 | J27: =總表!O82 | K27: =總表!H82
A28: 去程 | B28: 2026.07.15（三） | C28: G1074 | D28: 青島 → 濟南 | E28: 14:36–17:20 | F28: =總表!C50 | G28: =總表!D50 | H28: =總表!M50 | I28: =總表!N50 | J28: =總表!O50 | K28: =總表!H50
A29: 去程 | B29: 2026.07.15（三） | C29: G1074 | D29: 青島 → 濟南 | E29: 14:36–17:20 | F29: =總表!C51 | G29: =總表!D51 | H29: =總表!M51 | I29: =總表!N51 | J29: =總表!O51 | K29: =總表!H51
A30: 去程 | B30: 2026.07.15（三） | C30: G1074 | D30: 青島 → 濟南 | E30: 14:36–17:20 | F30: =總表!C24 | G30: =總表!D24 | H30: =總表!M24 | I30: =總表!N24 | J30: =總表!O24 | K30: =總表!H24
A31: 去程 | B31: 2026.07.15（三） | C31: G1074 | D31: 青島 → 濟南 | E31: 14:36–17:20 | F31: =總表!C23 | G31: =總表!D23 | H31: =總表!M23 | I31: =總表!N23 | J31: =總表!O23 | K31: =總表!H23
A32: 去程 | B32: 2026.07.15（三） | C32: G1074 | D32: 青島 → 濟南 | E32: 14:36–17:20 | F32: =總表!C29 | G32: =總表!D29 | H32: =總表!M29 | I32: =總表!N29 | J32: =總表!O29 | K32: =總表!H29
A33: 去程 | B33: 2026.07.15（三） | C33: G1074 | D33: 青島 → 濟南 | E33: 14:36–17:20 | F33: =總表!C30 | G33: =總表!D30 | H33: =總表!M30 | I33: =總表!N30 | J33: =總表!O30 | K33: =總表!H30
A34: 去程 | B34: 2026.07.15（三） | C34: G1074 | D34: 青島 → 濟南 | E34: 14:36–17:20 | F34: =總表!C25 | G34: =總表!D25 | H34: =總表!M25 | I34: =總表!N25 | J34: =總表!O25 | K34: =總表!H25
A35: 去程 | B35: 2026.07.15（三） | C35: G1074 | D35: 青島 → 濟南 | E35: 14:36–17:20 | F35: =總表!C37 | G35: =總表!D37 | H35: =總表!M37 | I35: =總表!N37 | J35: =總表!O37 | K35: =總表!H37
A36: 去程 | B36: 2026.07.15（三） | C36: G1074 | D36: 青島 → 濟南 | E36: 14:36–17:20 | F36: =總表!C28 | G36: =總表!D28 | H36: =總表!M28 | I36: =總表!N28 | J36: =總表!O28 | K36: =總表!H28
A37: 去程 | B37: 2026.07.15（三） | C37: G1074 | D37: 青島 → 濟南 | E37: 14:36–17:20 | F37: =總表!C31 | G37: =總表!D31 | H37: =總表!M31 | I37: =總表!N31 | J37: =總表!O31 | K37: =總表!H31
A38: 去程 | B38: 2026.07.15（三） | C38: G1074 | D38: 青島 → 濟南 | E38: 14:36–17:20 | F38: =總表!C27 | G38: =總表!D27 | H38: =總表!M27 | I38: =總表!N27 | J38: =總表!O27 | K38: =總表!H27
A39: 去程 | B39: 2026.07.15（三） | C39: G1074 | D39: 青島 → 濟南 | E39: 14:36–17:20 | F39: =總表!C32 | G39: =總表!D32 | H39: =總表!M32 | I39: =總表!N32 | J39: =總表!O32 | K39: =總表!H32
A40: 去程 | B40: 2026.07.15（三） | C40: G1074 | D40: 青島 → 濟南 | E40: 14:36–17:20 | F40: =總表!C86 | G40: =總表!D86 | H40: =總表!M86 | I40: =總表!N86 | J40: =總表!O86 | K40: =總表!H86
...

Sheet 檢核
A1: 項目 | B1: 數量 | C1: 說明
A2: 總表人數 | B2: 85
A3: 桌次已列 | B3: 85 | C3: 第1–4桌各10人；第5–9桌各9人
A4: 遊覽車次已列 | B4: 85 | C4: 第一車42人；第二車43人
A5: 去程高鐵座位已列 | B5: 85 | C5: G1074 青島→濟南
A6: 回程高鐵座位已列 | B6: 85 | C6: G5597 濟南→青島機場
A7: 資料版本 | B7: 2026.07.15 | C7: 青島與濟南住宿房號皆已列
A8: 青島房號已列 | B8: 85 | C8: 來源：分房表(1)(1).pdf；青島金水皇冠假日飯店
A9: 濟南房號已列 | B9: 85 | C9: 來源：使用者更新 Excel，2026.07.15 已同步至網頁
A10: 房號校正 | B10: 85 | C10: 2026.07.14 改用姓名對應 PDF 房號，避免總表編號順序差異造成錯位
A11: 編號校正 | B11: 4 | C11: 47 顏明儀；48 王思嵐；51 傅佳旻；52 徐維鈴
