Workbook

Sheet 總表
A1: 濟南房號與桌次總表
A2: 整合來源：分房、桌次、晚宴、高鐵、遊覽車。名單共 85 人；房間 44 間；桌次 9 桌；遊覽車 2 車。
A3: 車次：青島 → 濟南｜2026/07/15｜高鐵 G1074｜14:36–17:20｜座位名單 85 人；全員座位已列
A4: 房號 | B4: 編號 | C4: 姓名 | D4: 單位 | E4: 性別 | F4: 青島金水皇冠假日飯店房號 | G4: 濟南美悅雲禧飯店房號 | H4: 桌次 | I4: 晚宴座位 | J4: 課程分組 | K4: 組長 | L4: 備註 | M4: 車廂 | N4: 座位 | O4: 遊覽車次
A5: 1 | B5: 1 | C5: 許智雄 | D5: 高天通訊處 | E5: 男 | H5: 第1桌 | I5: 第9桌 | J5: 第9組 | K5: 組長 | M5: 14 | N5: 04D | O5: 第1車
A6: 1 | B6: 2 | C6: 謝政男 | D6: 高天通訊處 | E6: 男 | H6: 第1桌 | I6: 第6桌 | J6: 第6組 | M6: 14 | N6: 04C | O6: 第1車
A7: 2 | B7: 3 | C7: 何宜家 | D7: 高天通訊處 | E7: 女 | H7: 第1桌 | I7: 主桌 | M7: 14 | N7: 04B | O7: 第1車
A8: 2 | B8: 4 | C8: 蕭宇晴 | D8: 高天通訊處 | E8: 女 | H8: 第1桌 | I8: 第2桌 | J8: 第2組 | M8: 14 | N8: 05C | O8: 第1車
A9: 3 | B9: 5 | C9: 蕭如菁 | D9: 高天通訊處 | E9: 女 | H9: 第1桌 | I9: 第3桌 | J9: 第3組 | M9: 14 | N9: 04F | O9: 第1車
A10: 3 | B10: 6 | C10: 何宜庭 | D10: 高天通訊處 | E10: 女 | H10: 第1桌 | I10: 第8桌 | J10: 第8組 | M10: 14 | N10: 05B | O10: 第1車
A11: 4 | B11: 7 | C11: 戴東志 | D11: 高天通訊處 | E11: 男 | H11: 第1桌 | I11: 第1桌 | J11: 第1組 | M11: 14 | N11: 04A | O11: 第1車
A12: 4 | B12: 8 | C12: 詹政杰 | D12: 高天通訊處 | E12: 男 | H12: 第1桌 | I12: 第7桌 | J12: 第7組 | M12: 14 | N12: 05A | O12: 第1車
A13: 5 | B13: 9 | C13: 吳睿綝 | D13: 高天通訊處 | E13: 女 | H13: 第1桌 | I13: 第9桌 | J13: 第9組 | M13: 14 | N13: 05D | O13: 第1車
A14: 5 | B14: 10 | C14: 陳懷柔 | D14: 高天通訊處 | E14: 女 | H14: 第1桌 | I14: 第7桌 | J14: 第7組 | M14: 14 | N14: 05F | O14: 第1車
A15: 6 | B15: 11 | C15: 黃柏瑞 | D15: 高貴通訊處 | E15: 男 | H15: 第2桌 | I15: 第1桌 | J15: 第1組 | K15: 組長 | M15: 14 | N15: 06A | O15: 第1車
A16: 6 | B16: 12 | C16: 陳其呈 | D16: 高貴通訊處 | E16: 男 | H16: 第2桌 | I16: 第2桌 | J16: 第2組 | M16: 14 | N16: 06B | O16: 第1車
A17: 7 | B17: 13 | C17: 陳武均 | D17: 富予二通訊處 | E17: 男 | H17: 第6桌 | I17: 第5桌 | J17: 第5組 | M17: 14 | N17: 06C | O17: 第2車
A18: 7 | B18: 14 | C18: 陳尚禾 | D18: 富予二通訊處 | E18: 男 | H18: 第6桌 | I18: 第5桌 | J18: 第5組 | M18: 14 | N18: 06D | O18: 第2車
A19: 8 | B19: 15 | C19: 陳昶聿 | D19: 富予二通訊處 | E19: 男 | H19: 第6桌 | I19: 第7桌 | J19: 第7組 | K19: 組長 | M19: 14 | N19: 07A | O19: 第2車
A20: 8 | B20: 16 | C20: 宋里安 | D20: 富予二通訊處 | E20: 男 | H20: 第6桌 | I20: 第3桌 | J20: 第3組 | K20: 組長 | M20: 14 | N20: 07C | O20: 第2車
A21: 9 | B21: 17 | C21: 賴芯甯 | D21: 富予二通訊處 | E21: 女 | H21: 第6桌 | I21: 第2桌 | J21: 第2組 | M21: 14 | N21: 06F | O21: 第2車
A22: 9 | B22: 18 | C22: 高泰琳 | D22: 富予二通訊處 | E22: 女 | H22: 第6桌 | I22: 第4桌 | J22: 第4組 | M22: 14 | N22: 07D | O22: 第2車
A23: 10 | B23: 19 | C23: 許瓊云 | D23: 富予二通訊處 | E23: 女 | H23: 第6桌 | I23: 第6桌 | J23: 第6組 | M23: 14 | N23: 07B | O23: 第2車
A24: 10 | B24: 20 | C24: 王姵慈 | D24: 富吳通訊處 | E24: 女 | H24: 第8桌 | I24: 第2桌 | J24: 第2組 | M24: 14 | N24: 12F | O24: 第2車
A25: 11 | B25: 21 | C25: 賴含怡 | D25: 富則通訊處 | E25: 女 | H25: 第5桌 | I25: 第4桌 | J25: 第4組 | M25: 14 | N25: 14D | O25: 第2車
A26: 11 | B26: 22 | C26: 吳佩姗 | D26: 富吳通訊處 | E26: 女 | H26: 第9桌 | I26: 第2桌 | J26: 第2組 | M26: 14 | N26: 09B | O26: 第2車
A27: 12 | B27: 23 | C27: 王鄆郅 | D27: 富吳通訊處 | E27: 男 | H27: 第9桌 | I27: 第5桌 | J27: 第5組 | M27: 14 | N27: 09A | O27: 第2車
A28: 12 | B28: 24 | C28: 廖冠傑 | D28: 富吳通訊處 | E28: 男 | H28: 第9桌 | I28: 第3桌 | J28: 第3組 | M28: 14 | N28: 09F | O28: 第2車
A29: 13 | B29: 25 | C29: 王騌捷 | D29: 富吳通訊處 | E29: 男 | H29: 第8桌 | I29: 第1桌 | J29: 第1組 | M29: 14 | N29: 13A | O29: 第2車
A30: 13 | B30: 26 | C30: 黃金隆 | D30: 富吳通訊處 | E30: 男 | H30: 第9桌 | I30: 第3桌 | J30: 第3組 | M30: 14 | N30: 10D | O30: 第2車
A31: 14 | B31: 27 | C31: 呂顏伃 | D31: 富吳通訊處 | E31: 女 | H31: 第9桌 | I31: 第8桌 | J31: 第8組 | M31: 14 | N31: 10B | O31: 第2車
A32: 14 | B32: 28 | C32: 陳怡諳 | D32: 富吳通訊處 | E32: 女 | H32: 第9桌 | I32: 第8桌 | J32: 第8組 | M32: 14 | N32: 09C | O32: 第2車
... A44: 20 | B44: 40 | C44: 侯宏詣 | D44: 富則通訊處 | E44: 男 | H44: 第8桌 | I44: 第2桌 | J44: 第2組 | M44: 14 | N44: 12D | O44: 第2車
A45: 21 | B45: 41 | C45: 簡宏鈞 | D45: 富能通訊處 | E45: 男 | H45: 第3桌 | I45: 主桌 | M45: 14 | N45: 13B | O45: 第1車
A46: 21 | B46: 42 | C46: 王昱文 | D46: 富則通訊處 | E46: 男 | H46: 第7桌 | I46: 第9桌 | J46: 第9組 | M46: 14 | N46: 16F | O46: 第2車
A47: 22 | B47: 43 | C47: 管卓鈞 | D47: 富能通訊處 | E47: 女 | H47: 第4桌 | I47: 第5桌 | J47: 第5組 | M47: 14 | N47: 13C | O47: 第1車
A48: 22 | B48: 44 | C48: 林桂安 | D48: 富則通訊處 | E48: 女 | H48: 第7桌 | I48: 第3桌 | J48: 第3組 | M48: 14 | N48: 15B | O48: 第2車
A49: 23 | B49: 45 | C49: 簡姵萱 | D49: 富能通訊處 | E49: 女 | H49: 第4桌 | I49: 第7桌 | J49: 第7組 | M49: 14 | N49: 13D | O49: 第1車
A50: 23 | B50: 46 | C50: 潘韻竹 | D50: 富則通訊處 | E50: 女 | H50: 第4桌 | I50: 第8桌 | J50: 第8組 | M50: 14 | N50: 16D | O50: 第1車
A51: 24 | B51: 47 | C51: 傅佳旻 | D51: 富占通訊處 | E51: 女 | H51: 第3桌 | I51: 第8桌 | J51: 第8組 | M51: 14 | N51: 07F | O51: 第1車
...

Sheet 桌次
A1: 用餐桌次名單
A2: 依最新桌次整理｜共 85 人、9 桌；內容與總表連動。
A4: 桌次 | B4: 姓名 | C4: 單位 | D4: 性別 | E4: 房號 | F4: 編號 | G4: 青島房號 | H4: 濟南房號
A5: =總表!H5 -> 第1桌 | B5: =總表!C5 -> 許智雄 | C5: =總表!D5 -> 高天通訊處 | D5: =總表!E5 -> 男 | E5: =總表!A5 -> 1 | F5: =總表!B5 -> 1 | G5: =IF(總表!F5="","",總表!F5) | H5: =IF(總表!G5="","",總表!G5)
A6: =總表!H6 -> 第1桌 | B6: =總表!C6 -> 謝政男 | C6: =總表!D6 -> 高天通訊處 | D6: =總表!E6 -> 男 | E6: =總表!A6 -> 1 | F6: =總表!B6 -> 2 | G6: =IF(總表!F6="","",總表!F6) | H6: =IF(總表!G6="","",總表!G6)
A7: =總表!H7 -> 第1桌 | B7: =總表!C7 -> 何宜家 | C7: =總表!D7 -> 高天通訊處 | D7: =總表!E7 -> 女 | E7: =總表!A7 -> 2 | F7: =總表!B7 -> 3 | G7: =IF(總表!F7="","",總表!F7) | H7: =IF(總表!G7="","",總表!G7)
A8: =總表!H8 -> 第1桌 | B8: =總表!C8 -> 蕭宇晴 | C8: =總表!D8 -> 高天通訊處 | D8: =總表!E8 -> 女 | E8: =總表!A8 -> 2 | F8: =總表!B8 -> 4 | G8: =IF(總表!F8="","",總表!F8) | H8: =IF(總表!G8="","",總表!G8)
A9: =總表!H9 -> 第1桌 | B9: =總表!C9 -> 蕭如菁 | C9: =總表!D9 -> 高天通訊處 | D9: =總表!E9 -> 女 | E9: =總表!A9 -> 3 | F9: =總表!B9 -> 5 | G9: =IF(總表!F9="","",總表!F9) | H9: =IF(總表!G9="","",總表!G9)
A10: =總表!H10 -> 第1桌 | B10: =總表!C10 -> 何宜庭 | C10: =總表!D10 -> 高天通訊處 | D10: =總表!E10 -> 女 | E10: =總表!A10 -> 3 | F10: =總表!B10 -> 6 | G10: =IF(總表!F10="","",總表!F10) | H10: =IF(總表!G10="","",總表!G10)
A11: =總表!H11 -> 第1桌 | B11: =總表!C11 -> 戴東志 | C11: =總表!D11 -> 高天通訊處 | D11: =總表!E11 -> 男 | E11: =總表!A11 -> 4 | F11: =總表!B11 -> 7 | G11: =IF(總表!F11="","",總表!F11) | H11: =IF(總表!G11="","",總表!G11)
A12: =總表!H12 -> 第1桌 | B12: =總表!C12 -> 詹政杰 | C12: =總表!D12 -> 高天通訊處 | D12: =總表!E12 -> 男 | E12: =總表!A12 -> 4 | F12: =總表!B12 -> 8 | G12: =IF(總表!F12="","",總表!F12) | H12: =IF(總表!G12="","",總表!G12)
A13: =總表!H13 -> 第1桌 | B13: =總表!C13 -> 吳睿綝 | C13: =總表!D13 -> 高天通訊處 | D13: =總表!E13 -> 女 | E13: =總表!A13 -> 5 | F13: =總表!B13 -> 9 | G13: =IF(總表!F13="","",總表!F13) | H13: =IF(總表!G13="","",總表!G13)
A14: =總表!H14 -> 第1桌 | B14: =總表!C14 -> 陳懷柔 | C14: =總表!D14 -> 高天通訊處 | D14: =總表!E14 -> 女 | E14: =總表!A14 -> 5 | F14: =總表!B14 -> 10 | G14: =IF(總表!F14="","",總表!F14) | H14: =IF(總表!G14="","",總表!G14)
A15: =總表!H15 -> 第2桌 | B15: =總表!C15 -> 黃柏瑞 | C15: =總表!D15 -> 高貴通訊處 | D15: =總表!E15 -> 男 | E15: =總表!A15 -> 6 | F15: =總表!B15 -> 11 | G15: =IF(總表!F15="","",總表!F15) | H15: =IF(總表!G15="","",總表!G15)
A16: =總表!H16 -> 第2桌 | B16: =總表!C16 -> 陳其呈 | C16: =總表!D16 -> 高貴通訊處 | D16: =總表!E16 -> 男 | E16: =總表!A16 -> 6 | F16: =總表!B16 -> 12 | G16: =IF(總表!F16="","",總表!F16) | H16: =IF(總表!G16="","",總表!G16)
A17: =總表!H71 -> 第2桌 | B17: =總表!C71 -> 張祐珮 | C17: =總表!D71 -> 富后通訊處 | D17: =總表!E71 -> 女 | E17: =總表!A71 -> 34 | F17: =總表!B71 -> 67 | G17: =IF(總表!F71="","",總表!F71) | H17: =IF(總表!G71="","",總表!G71)
A18: =總表!H72 -> 第2桌 | B18: =總表!C72 -> 施昕余 | C18: =總表!D72 -> 中銘通訊處 | D18: =總表!E72 -> 女 | E18: =總表!A72 -> 34 | F18: =總表!B72 -> 68 | G18: =IF(總表!F72="","",總表!F72) | H18: =IF(總表!G72="","",總表!G72)
A19: =總表!H73 -> 第2桌 | B19: =總表!C73 -> 吳皓誠 | C19: =總表!D73 -> 富亨通訊處 | D19: =總表!E73 -> 男 | E19: =總表!A73 -> 35 | F19: =總表!B73 -> 69 | G19: =IF(總表!F73="","",總表!F73) | H19: =IF(總表!G73="","",總表!G73)
A20: =總表!H74 -> 第2桌 | B20: =總表!C74 -> 張家瑋 | C20: =總表!D74 -> 富亨通訊處 | D20: =總表!E74 -> 男 | E20: =總表!A74 -> 35 | F20: =總表!B74 -> 70 | G20: =IF(總表!F74="","",總表!F74) | H20: =IF(總表!G74="","",總表!G74)
A21: =總表!H75 -> 第2桌 | B21: =總表!C75 -> 馬英傑 | C21: =總表!D75 -> 富亨通訊處 | D21: =總表!E75 -> 男 | E21: =總表!A75 -> 36 | F21: =總表!B75 -> 71 | G21: =IF(總表!F75="","",總表!F75) | H21: =IF(總表!G75="","",總表!G75)
A22: =總表!H76 -> 第2桌 | B22: =總表!C76 -> 林宏威 | C22: =總表!D76 -> 富亨通訊處 | D22: =總表!E76 -> 男 | E22: =總表!A76 -> 36 | F22: =總表!B76 -> 72 | G22: =IF(總表!F76="","",總表!F76) | H22: =IF(總表!G76="","",總表!G76)
A23: =總表!H77 -> 第2桌 | B23: =總表!C77 -> 陳怡萍 | C23: =總表!D77 -> 富亨通訊處 | D23: =總表!E77 -> 女 | E23: =總表!A77 -> 37 | F23: =總表!B77 -> 73 | G23: =IF(總表!F77="","",總表!F77) | H23: =IF(總表!G77="","",總表!G77)
A24: =總表!H78 -> 第2桌 | B24: =總表!C78 -> 廖家慧 | C24: =總表!D78 -> 富亨通訊處 | D24: =總表!E78 -> 女 | E24: =總表!A78 -> 37 | F24: =總表!B78 -> 74 | G24: =IF(總表!F78="","",總表!F78) | H24: =IF(總表!G78="","",總表!G78)
A25: =總表!H45 -> 第3桌 | B25: =總表!C45 -> 簡宏鈞 | C25: =總表!D45 -> 富能通訊處 | D25: =總表!E45 -> 男 | E25: =總表!A45 -> 21 | F25: =總表!B45 -> 41 | G25: =IF(總表!F45="","",總表!F45) | H25: =IF(總表!G45="","",總表!G45)
A26: =總表!H51 -> 第3桌 | B26: =總表!C51 -> 傅佳旻 | C26: =總表!D51 -> 富占通訊處 | D26: =總表!E51 -> 女 | E26: =總表!A51 -> 24 | F26: =總表!B51 -> 47 | G26: =IF(總表!F51="","",總表!F51) | H26: =IF(總表!G51="","",總表!G51)
A27: =總表!H52 -> 第3桌 | B27: =總表!C52 -> 徐維鈴 | C27: =總表!D52 -> 富占通訊處 | D27: =總表!E52 -> 女 | E27: =總表!A52 -> 24 | F27: =總表!B52 -> 48 | G27: =IF(總表!F52="","",總表!F52) | H27: =IF(總表!G52="","",總表!G52)
A28: =總表!H53 -> 第3桌 | B28: =總表!C53 -> 鍾怡婷 | C28: =總表!D53 -> 富占通訊處 | D28: =總表!E53 -> 女 | E28: =總表!A53 -> 25 | F28: =總表!B53 -> 49 | G28: =IF(總表!F53="","",總表!F53) | H28: =IF(總表!G53="","",總表!G53)
A29: =總表!H54 -> 第3桌 | B29: =總表!C54 -> 林宜潔 | C29: =總表!D54 -> 富占通訊處 | D29: =總表!E54 -> 女 | E29: =總表!A54 -> 25 | F29: =總表!B54 -> 50 | G29: =IF(總表!F54="","",總表!F54) | H29: =IF(總表!G54="","",總表!G54)
A30: =總表!H65 -> 第3桌 | B30: =總表!C65 -> 蔡承遠 | C30: =總表!D65 -> 富則通訊處 | D30: =總表!E65 -> 男 | E30: =總表!A65 -> 31 | F30: =總表!B65 -> 61 | G30: =IF(總表!F65="","",總表!F65) | H30: =IF(總表!G65="","",總表!G65)
A31: =總表!H66 -> 第3桌 | B31: =總表!C66 -> 張國興 | C31: =總表!D66 -> 富則通訊處 | D31: =總表!E66 -> 男 | E31: =總表!A66 -> 31 | F31: =總表!B66 -> 62 | G31: =IF(總表!F66="","",總表!F66) | H31: =IF(總表!G66="","",總表!G66)
A32: =總表!H85 -> 第3桌 | B32: =總表!C85 -> 鄭占禮 | C32: =總表!D85 -> 富占通訊處 | D32: =總表!E85 -> 男 | E32: =總表!A85 -> 41 | F32: =總表!B85 -> 81 | G32: =IF(總表!F85="","",總表!F85) -> 1111 | H32: =IF(總表!G85="","",總表!G85) -> 2222
A33: =總表!H86 -> 第3桌 | B33: =總表!C86 -> 孫振文 | C33: =總表!D86 -> 富北通訊處 | D33: =總表!E86 -> 男 | E33: =總表!A86 -> 41 | F33: =總表!B86 -> 82 | G33: =IF(總表!F86="","",總表!F86) | H33: =IF(總表!G86="","",總表!G86)
A34: =總表!H87 -> 第3桌 | B34: =總表!C87 -> 范毓斌 | C34: =總表!D87 -> 富占通訊處 | D34: =總表!E87 -> 男 | E34: =總表!A87 -> 42 | F34: =總表!B87 -> 83 | G34: =IF(總表!F87="","",總表!F87) | H34: =IF(總表!G87="","",總表!G87)
A35: =總表!H47 -> 第4桌 | B35: =總表!C47 -> 管卓鈞 | C35: =總表!D47 -> 富能通訊處 | D35: =總表!E47 -> 女 | E35: =總表!A47 -> 22 | F35: =總表!B47 -> 43 | G35: =IF(總表!F47="","",總表!F47) | H35: =IF(總表!G47="","",總表!G47)
A36: =總表!H49 -> 第4桌 | B36: =總表!C49 -> 簡姵萱 | C36: =總表!D49 -> 富能通訊處 | D36: =總表!E49 -> 女 | E36: =總表!A49 -> 23 | F36: =總表!B49 -> 45 | G36: =IF(總表!F49="","",總表!F49) | H36: =IF(總表!G49="","",總表!G49)
A37: =總表!H50 -> 第4桌 | B37: =總表!C50 -> 潘韻竹 | C37: =總表!D50 -> 富則通訊處 | D37: =總表!E50 -> 女 | E37: =總表!A50 -> 23 | F37: =總表!B50 -> 46 | G37: =IF(總表!F50="","",總表!F50) | H37: =IF(總表!G50="","",總表!G50)
A38: =總表!H55 -> 第4桌 | B38: =總表!C55 -> 顏明儀 | C38: =總表!D55 -> 富則通訊處 | D38: =總表!E55 -> 女 | E38: =總表!A55 -> 26 | F38: =總表!B55 -> 51 | G38: =IF(總表!F55="","",總表!F55) | H38: =IF(總表!G55="","",總表!G55)
A39: =總表!H56 -> 第4桌 | B39: =總表!C56 -> 王思嵐 | C39: =總表!D56 -> 富則通訊處 | D39: =總表!E56 -> 女 | E39: =總表!A56 -> 26 | F39: =總表!B56 -> 52 | G39: =IF(總表!F56="","",總表!F56) | H39: =IF(總表!G56="","",總表!G56)
A40: =總表!H79 -> 第4桌 | B40: =總表!C79 -> 陳龍生 | C40: =總表!D79 -> 富鑽通訊處 | D40: =總表!E79 -> 男 | E40: =總表!A79 -> 38 | F40: =總表!B79 -> 75 | G40: =IF(總表!F79="","",總表!F79) | H40: =IF(總表!G79="","",總表!G79)
A41: =總表!H80 -> 第4桌 | B41: =總表!C80 -> 葉金玲 | C41: =總表!D80 -> 富鑽通訊處 | D41: =總表!E80 -> 女 | E41: =總表!A80 -> 38 | F41: =總表!B80 -> 76 | G41: =IF(總表!F80="","",總表!F80) | H41: =IF(總表!G80="","",總表!G80)
...

Sheet 晚宴
A1: 晚宴座位名單
A2: 依總表晚宴座位整理｜共 85 人；主桌及第 1～9 桌，含課程分組與組長。
A4: 晚宴座位 | B4: 課程分組 | C4: 組長 | D4: 姓名 | E4: 單位 | F4: 性別 | G4: 房號 | H4: 編號 | I4: 備註
A5: =總表!I7 -> 主桌 | B5: =IF(總表!J7="","",總表!J7) | C5: =IF(總表!K7="","",總表!K7) | D5: =總表!C7 -> 何宜家 | E5: =總表!D7 -> 高天通訊處 | F5: =總表!E7 -> 女 | G5: =總表!A7 -> 2 | H5: =總表!B7 -> 3 | I5: =IF(總表!L7="","",總表!L7)
A6: =總表!I45 -> 主桌 | B6: =IF(總表!J45="","",總表!J45) | C6: =IF(總表!K45="","",總表!K45) | D6: =總表!C45 -> 簡宏鈞 | E6: =總表!D45 -> 富能通訊處 | F6: =總表!E45 -> 男 | G6: =總表!A45 -> 21 | H6: =總表!B45 -> 41 | I6: =IF(總表!L45="","",總表!L45)
A7: =總表!I84 -> 主桌 | B7: =IF(總表!J84="","",總表!J84) | C7: =IF(總表!K84="","",總表!K84) | D7: =總表!C84 -> 王原軍 | E7: =總表!D84 -> 中沐通訊處 | F7: =總表!E84 -> 男 | G7: =總表!A84 -> 40 | H7: =總表!B84 -> 80 | I7: =IF(總表!L84="","",總表!L84)
A8: =總表!I85 -> 主桌 | B8: =IF(總表!J85="","",總表!J85) | C8: =IF(總表!K85="","",總表!K85) | D8: =總表!C85 -> 鄭占禮 | E8: =總表!D85 -> 富占通訊處 | F8: =總表!E85 -> 男 | G8: =總表!A85 -> 41 | H8: =總表!B85 -> 81 | I8: =IF(總表!L85="","",總表!L85)
A9: =總表!I86 -> 主桌 | B9: =IF(總表!J86="","",總表!J86) | C9: =IF(總表!K86="","",總表!K86) | D9: =總表!C86 -> 孫振文 | E9: =總表!D86 -> 富北通訊處 | F9: =總表!E86 -> 男 | G9: =總表!A86 -> 41 | H9: =總表!B86 -> 82 | I9: =IF(總表!L86="","",總表!L86)
A10: =總表!I89 -> 主桌 | B10: =IF(總表!J89="","",總表!J89) | C10: =IF(總表!K89="","",總表!K89) | D10: =總表!C89 -> 吳修毅 | E10: =總表!D89 -> 富吳通訊處 | F10: =總表!E89 -> 男 | G10: =總表!A89 -> 44 | H10: =總表!B89 -> 85 | I10: =IF(總表!L89="","",總表!L89)
A11: =總表!I11 -> 第1桌 | B11: =IF(總表!J11="","",總表!J11) -> 第1組 | C11: =IF(總表!K11="","",總表!K11) | D11: =總表!C11 -> 戴東志 | E11: =總表!D11 -> 高天通訊處 | F11: =總表!E11 -> 男 | G11: =總表!A11 -> 4 | H11: =總表!B11 -> 7 | I11: =IF(總表!L11="","",總表!L11)
A12: =總表!I15 -> 第1桌 | B12: =IF(總表!J15="","",總表!J15) -> 第1組 | C12: =IF(總表!K15="","",總表!K15) -> 組長 | D12: =總表!C15 -> 黃柏瑞 | E12: =總表!D15 -> 高貴通訊處 | F12: =總表!E15 -> 男 | G12: =總表!A15 -> 6 | H12: =總表!B15 -> 11 | I12: =IF(總表!L15="","",總表!L15)
A13: =總表!I29 -> 第1桌 | B13: =IF(總表!J29="","",總表!J29) -> 第1組 | C13: =IF(總表!K29="","",總表!K29) | D13: =總表!C29 -> 王騌捷 | E13: =總表!D29 -> 富吳通訊處 | F13: =總表!E29 -> 男 | G13: =總表!A29 -> 13 | H13: =總表!B29 -> 25 | I13: =IF(總表!L29="","",總表!L29)
A14: =總表!I39 -> 第1桌 | B14: =IF(總表!J39="","",總表!J39) -> 第1組 | C14: =IF(總表!K39="","",總表!K39) | D14: =總表!C39 -> 鄭丞哲 | E14: =總表!D39 -> 富吳通訊處 | F14: =總表!E39 -> 男 | G14: =總表!A39 -> 18 | H14: =總表!B39 -> 35 | I14: =IF(總表!L39="","",總表!L39)
A15: =總表!I52 -> 第1桌 | B15: =IF(總表!J52="","",總表!J52) -> 第1組 | C15: =IF(總表!K52="","",總表!K52) | D15: =總表!C52 -> 徐維鈴 | E15: =總表!D52 -> 富占通訊處 | F15: =總表!E52 -> 女 | G15: =總表!A52 -> 24 | H15: =總表!B52 -> 48 | I15: =IF(總表!L52="","",總表!L52)
A16: =總表!I59 -> 第1桌 | B16: =IF(總表!J59="","",總表!J59) -> 第1組 | C16: =IF(總表!K59="","",總表!K59) | D16: =總表!C59 -> 余妏珊 | E16: =總表!D59 -> 富則通訊處 | F16: =總表!E59 -> 女 | G16: =總表!A59 -> 28 | H16: =總表!B59 -> 55 | I16: =IF(總表!L59="","",總表!L59)
A17: =總表!I62 -> 第1桌 | B17: =IF(總表!J62="","",總表!J62) -> 第1組 | C17: =IF(總表!K62="","",總表!K62) | D17: =總表!C62 -> 李婕詠 | E17: =總表!D62 -> 富則通訊處 | F17: =總表!E62 -> 女 | G17: =總表!A62 -> 29 | H17: =總表!B62 -> 58 | I17: =IF(總表!L62="","",總表!L62)
A18: =總表!I73 -> 第1桌 | B18: =IF(總表!J73="","",總表!J73) -> 第1組 | C18: =IF(總表!K73="","",總表!K73) | D18: =總表!C73 -> 吳皓誠 | E18: =總表!D73 -> 富亨通訊處 | F18: =總表!E73 -> 男 | G18: =總表!A73 -> 35 | H18: =總表!B73 -> 69 | I18: =IF(總表!L73="","",總表!L73)
A19: =總表!I80 -> 第1桌 | B19: =IF(總表!J80="","",總表!J80) -> 第1組 | C19: =IF(總表!K80="","",總表!K80) | D19: =總表!C80 -> 葉金玲 | E19: =總表!D80 -> 富鑽通訊處 | F19: =總表!E80 -> 女 | G19: =總表!A80 -> 38 | H19: =總表!B80 -> 76 | I19: =IF(總表!L80="","",總表!L80)
A20: =總表!I8 -> 第2桌 | B20: =IF(總表!J8="","",總表!J8) -> 第2組 | C20: =IF(總表!K8="","",總表!K8) | D20: =總表!C8 -> 蕭宇晴 | E20: =總表!D8 -> 高天通訊處 | F20: =總表!E8 -> 女 | G20: =總表!A8 -> 2 | H20: =總表!B8 -> 4 | I20: =IF(總表!L8="","",總表!L8)
A21: =總表!I16 -> 第2桌 | B21: =IF(總表!J16="","",總表!J16) -> 第2組 | C21: =IF(總表!K16="","",總表!K16) | D21: =總表!C16 -> 陳其呈 | E21: =總表!D16 -> 高貴通訊處 | F21: =總表!E16 -> 男 | G21: =總表!A16 -> 6 | H21: =總表!B16 -> 12 | I21: =IF(總表!L16="","",總表!L16)
A22: =總表!I21 -> 第2桌 | B22: =IF(總表!J21="","",總表!J21) -> 第2組 | C22: =IF(總表!K21="","",總表!K21) | D22: =總表!C21 -> 賴芯甯 | E22: =總表!D21 -> 富予二通訊處 | F22: =總表!E21 -> 女 | G22: =總表!A21 -> 9 | H22: =總表!B21 -> 17 | I22: =IF(總表!L21="","",總表!L21)
A23: =總表!I24 -> 第2桌 | B23: =IF(總表!J24="","",總表!J24) -> 第2組 | C23: =IF(總表!K24="","",總表!K24) | D23: =總表!C24 -> 王姵慈 | E23: =總表!D24 -> 富吳通訊處 | F23: =總表!E24 -> 女 | G23: =總表!A24 -> 10 | H23: =總表!B24 -> 20 | I23: =IF(總表!L24="","",總表!L24)
A24: =總表!I26 -> 第2桌 | B24: =IF(總表!J26="","",總表!J26) -> 第2組 | C24: =IF(總表!K26="","",總表!K26) | D24: =總表!C26 -> 吳佩姗 | E24: =總表!D26 -> 富吳通訊處 | F24: =總表!E26 -> 女 | G24: =總表!A26 -> 11 | H24: =總表!B26 -> 22 | I24: =IF(總表!L26="","",總表!L26)
A25: =總表!I44 -> 第2桌 | B25: =IF(總表!J44="","",總表!J44) -> 第2組 | C25: =IF(總表!K44="","",總表!K44) | D25: =總表!C44 -> 侯宏詣 | E25: =總表!D44 -> 富則通訊處 | F25: =總表!E44 -> 男 | G25: =總表!A44 -> 20 | H25: =總表!B44 -> 40 | I25: =IF(總表!L44="","",總表!L44)
A26: =總表!I55 -> 第2桌 | B26: =IF(總表!J55="","",總表!J55) -> 第2組 | C26: =IF(總表!K55="","",總表!K55) -> 組長 | D26: =總表!C55 -> 顏明儀 | E26: =總表!D55 -> 富則通訊處 | F26: =總表!E55 -> 女 | G26: =總表!A55 -> 26 | H26: =總表!B55 -> 51 | I26: =IF(總表!L55="","",總表!L55)
A27: =總表!I67 -> 第2桌 | B27: =IF(總表!J67="","",總表!J67) -> 第2組 | C27: =IF(總表!K67="","",總表!K67) | D27: =總表!C67 -> 高智源 | E27: =總表!D67 -> 富則通訊處 | F27: =總表!E67 -> 男 | G27: =總表!A67 -> 32 | H27: =總表!B67 -> 63 | I27: =IF(總表!L67="","",總表!L67)
A28: =總表!I82 -> 第2桌 | B28: =IF(總表!J82="","",總表!J82) -> 第2組 | C28: =IF(總表!K82="","",總表!K82) | D28: =總表!C82 -> 林瑋 | E28: =總表!D82 -> 富北通訊處 | F28: =總表!E82 -> 男 | G28: =總表!A82 -> 39 | H28: =總表!B82 -> 78 | I28: =IF(總表!L82="","",總表!L82)
A29: =總表!I9 -> 第3桌 | B29: =IF(總表!J9="","",總表!J9) -> 第3組 | C29: =IF(總表!K9="","",總表!K9) | D29: =總表!C9 -> 蕭如菁 | E29: =總表!D9 -> 高天通訊處 | F29: =總表!E9 -> 女 | G29: =總表!A9 -> 3 | H29: =總表!B9 -> 5 | I29: =IF(總表!L9="","",總表!L9)
A30: =總表!I20 -> 第3桌 | B30: =IF(總表!J20="","",總表!J20) -> 第3組 | C30: =IF(總表!K20="","",總表!K20) -> 組長 | D30: =總表!C20 -> 宋里安 | E30: =總表!D20 -> 富予二通訊處 | F30: =總表!E20 -> 男 | G30: =總表!A20 -> 8 | H30: =總表!B20 -> 16 | I30: =IF(總表!L20="","",總表!L20)
A31: =總表!I28 -> 第3桌 | B31: =IF(總表!J28="","",總表!J28) -> 第3組 | C31: =IF(總表!K28="","",總表!K28) | D31: =總表!C28 -> 廖冠傑 | E31: =總表!D28 -> 富吳通訊處 | F31: =總表!E28 -> 男 | G31: =總表!A28 -> 12 | H31: =總表!B28 -> 24 | I31: =IF(總表!L28="","",總表!L28)
A32: =總表!I30 -> 第3桌 | B32: =IF(總表!J30="","",總表!J30) -> 第3組 | C32: =IF(總表!K30="","",總表!K30) | D32: =總表!C30 -> 黃金隆 | E32: =總表!D30 -> 富吳通訊處 | F32: =總表!E30 -> 男 | G32: =總表!A30 -> 13 | H32: =總表!B30 -> 26 | I32: =IF(總表!L30="","",總表!L30)
A33: =總表!I34 -> 第3桌 | B33: =IF(總表!J34="","",總表!J34) -> 第3組 | C33: =IF(總表!K34="","",總表!K34) | D33: =總表!C34 -> 陳盈蓁 | E33: =總表!D34 -> 富吳通訊處 | F33: =總表!E34 -> 女 | G33: =總表!A34 -> 15 | H33: =總表!B34 -> 30 | I33: =IF(總表!L34="","",總表!L34)
A34: =總表!I38 -> 第3桌 | B34: =IF(總表!J38="","",總表!J38) -> 第3組 | C34: =IF(總表!K38="","",總表!K38) | D34: =總表!C38 -> 黃彥融 | E34: =總表!D38 -> 富吳通訊處 | F34: =總表!E38 -> 男 | G34: =總表!A38 -> 17 | H34: =總表!B38 -> 34 | I34: =IF(總表!L38="","",總表!L38)
A35: =總表!I48 -> 第3桌 | B35: =IF(總表!J48="","",總表!J48) -> 第3組 | C35: =IF(總表!K48="","",總表!K48) | D35: =總表!C48 -> 林桂安 | E35: =總表!D48 -> 富則通訊處 | F35: =總表!E48 -> 女 | G35: =總表!A48 -> 22 | H35: =總表!B48 -> 44 | I35: =IF(總表!L48="","",總表!L48)
A36: =總表!I68 -> 第3桌 | B36: =IF(總表!J68="","",總表!J68) -> 第3組 | C36: =IF(總表!K68="","",總表!K68) | D36: =總表!C68 -> 王銘宏 | E36: =總表!D68 -> 富則通訊處 | F36: =總表!E68 -> 男 | G36: =總表!A68 -> 32 | H36: =總表!B68 -> 64 | I36: =IF(總表!L68="","",總表!L68)
A37: =總表!I74 -> 第3桌 | B37: =IF(總表!J74="","",總表!J74) -> 第3組 | C37: =IF(總表!K74="","",總表!K74) | D37: =總表!C74 -> 張家瑋 | E37: =總表!D74 -> 富亨通訊處 | F37: =總表!E74 -> 男 | G37: =總表!A74 -> 35 | H37: =總表!B74 -> 70 | I37: =IF(總表!L74="","",總表!L74)
A38: =總表!I22 -> 第4桌 | B38: =IF(總表!J22="","",總表!J22) -> 第4組 | C38: =IF(總表!K22="","",總表!K22) | D38: =總表!C22 -> 高泰琳 | E38: =總表!D22 -> 富予二通訊處 | F38: =總表!E22 -> 女 | G38: =總表!A22 -> 9 | H38: =總表!B22 -> 18 | I38: =IF(總表!L22="","",總表!L22)
A39: =總表!I25 -> 第4桌 | B39: =IF(總表!J25="","",總表!J25) -> 第4組 | C39: =IF(總表!K25="","",總表!K25) | D39: =總表!C25 -> 賴含怡 | E39: =總表!D25 -> 富則通訊處 | F39: =總表!E25 -> 女 | G39: =總表!A25 -> 11 | H39: =總表!B25 -> 21 | I39: =IF(總表!L25="","",總表!L25)
A40: =總表!I61 -> 第4桌 | B40: =IF(總表!J61="","",總表!J61) -> 第4組 | C40: =IF(總表!K61="","",總表!K61) | D40: =總表!C61 -> 吳沛錞 | E40: =總表!D61 -> 富則通訊處 | F40: =總表!E61 -> 女 | G40: =總表!A61 -> 29 | H40: =總表!B61 -> 57 | I40: =IF(總表!L61="","",總表!L61)
A41: =總表!I66 -> 第4桌 | B41: =IF(總表!J66="","",總表!J66) -> 第4組 | C41: =IF(總表!K66="","",總表!K66) | D41: =總表!C66 -> 張國興 | E41: =總表!D66 -> 富則通訊處 | F41: =總表!E66 -> 男 | G41: =總表!A66 -> 31 | H41: =總表!B66 -> 62 | I41: =IF(總表!L66="","",總表!L66)
...

Sheet 檢核
A1: 資料檢核
A3: 項目 | B3: 數量 | C3: 名單／說明
A4: 總表人數 | B4: 85
A5: 桌次有、分房未找到 | B5: 0
A6: 晚宴有、分房未找到 | B6: 0
A7: 分房有、桌次未找到 | B7: 0
A8: 分房有、晚宴未找到 | B8: 0
A9: 車次座位已列 | B9: 85 | C9: 青島→濟南 G1074
A10: 車次座位未列 | B10: 0
A11: 遊覽車次已列 | B11: 85 | C11: 第1車 42 人；第2車 43 人
A12: 遊覽車次未列 | B12: 0

Sheet 遊覽車次
A1: 遊覽車次名單
A2: 依最新車次整理｜共 85 人；第1車 42 人、第2車 43 人。
A4: 遊覽車次 | B4: 姓名 | C4: 單位 | D4: 性別 | E4: 房號 | F4: 編號 | G4: 用餐桌次 | H4: 晚宴桌次
A5: =總表!O11 -> 第1車 | B5: =總表!C11 -> 戴東志 | C5: =總表!D11 -> 高天通訊處 | D5: =總表!E11 -> 男 | E5: =總表!A11 -> 4 | F5: =總表!B11 -> 7 | G5: =總表!H11 -> 第1桌 | H5: =總表!I11 -> 第1桌
A6: =總表!O7 -> 第1車 | B6: =總表!C7 -> 何宜家 | C6: =總表!D7 -> 高天通訊處 | D6: =總表!E7 -> 女 | E6: =總表!A7 -> 2 | F6: =總表!B7 -> 3 | G6: =總表!H7 -> 第1桌 | H6: =總表!I7 -> 主桌
A7: =總表!O6 -> 第1車 | B7: =總表!C6 -> 謝政男 | C7: =總表!D6 -> 高天通訊處 | D7: =總表!E6 -> 男 | E7: =總表!A6 -> 1 | F7: =總表!B6 -> 2 | G7: =總表!H6 -> 第1桌 | H7: =總表!I6 -> 第6桌
A8: =總表!O5 -> 第1車 | B8: =總表!C5 -> 許智雄 | C8: =總表!D5 -> 高天通訊處 | D8: =總表!E5 -> 男 | E8: =總表!A5 -> 1 | F8: =總表!B5 -> 1 | G8: =總表!H5 -> 第1桌 | H8: =總表!I5 -> 第9桌
A9: =總表!O9 -> 第1車 | B9: =總表!C9 -> 蕭如菁 | C9: =總表!D9 -> 高天通訊處 | D9: =總表!E9 -> 女 | E9: =總表!A9 -> 3 | F9: =總表!B9 -> 5 | G9: =總表!H9 -> 第1桌 | H9: =總表!I9 -> 第3桌
A10: =總表!O12 -> 第1車 | B10: =總表!C12 -> 詹政杰 | C10: =總表!D12 -> 高天通訊處 | D10: =總表!E12 -> 男 | E10: =總表!A12 -> 4 | F10: =總表!B12 -> 8 | G10: =總表!H12 -> 第1桌 | H10: =總表!I12 -> 第7桌
A11: =總表!O10 -> 第1車 | B11: =總表!C10 -> 何宜庭 | C11: =總表!D10 -> 高天通訊處 | D11: =總表!E10 -> 女 | E11: =總表!A10 -> 3 | F11: =總表!B10 -> 6 | G11: =總表!H10 -> 第1桌 | H11: =總表!I10 -> 第8桌
A12: =總表!O8 -> 第1車 | B12: =總表!C8 -> 蕭宇晴 | C12: =總表!D8 -> 高天通訊處 | D12: =總表!E8 -> 女 | E12: =總表!A8 -> 2 | F12: =總表!B8 -> 4 | G12: =總表!H8 -> 第1桌 | H12: =總表!I8 -> 第2桌
A13: =總表!O13 -> 第1車 | B13: =總表!C13 -> 吳睿綝 | C13: =總表!D13 -> 高天通訊處 | D13: =總表!E13 -> 女 | E13: =總表!A13 -> 5 | F13: =總表!B13 -> 9 | G13: =總表!H13 -> 第1桌 | H13: =總表!I13 -> 第9桌
A14: =總表!O14 -> 第1車 | B14: =總表!C14 -> 陳懷柔 | C14: =總表!D14 -> 高天通訊處 | D14: =總表!E14 -> 女 | E14: =總表!A14 -> 5 | F14: =總表!B14 -> 10 | G14: =總表!H14 -> 第1桌 | H14: =總表!I14 -> 第7桌
A15: =總表!O15 -> 第1車 | B15: =總表!C15 -> 黃柏瑞 | C15: =總表!D15 -> 高貴通訊處 | D15: =總表!E15 -> 男 | E15: =總表!A15 -> 6 | F15: =總表!B15 -> 11 | G15: =總表!H15 -> 第2桌 | H15: =總表!I15 -> 第1桌
A16: =總表!O16 -> 第1車 | B16: =總表!C16 -> 陳其呈 | C16: =總表!D16 -> 高貴通訊處 | D16: =總表!E16 -> 男 | E16: =總表!A16 -> 6 | F16: =總表!B16 -> 12 | G16: =總表!H16 -> 第2桌 | H16: =總表!I16 -> 第2桌
A17: =總表!O77 -> 第1車 | B17: =總表!C77 -> 陳怡萍 | C17: =總表!D77 -> 富亨通訊處 | D17: =總表!E77 -> 女 | E17: =總表!A77 -> 37 | F17: =總表!B77 -> 73 | G17: =總表!H77 -> 第2桌 | H17: =總表!I77 -> 第4桌
A18: =總表!O78 -> 第1車 | B18: =總表!C78 -> 廖家慧 | C18: =總表!D78 -> 富亨通訊處 | D18: =總表!E78 -> 女 | E18: =總表!A78 -> 37 | F18: =總表!B78 -> 74 | G18: =總表!H78 -> 第2桌 | H18: =總表!I78 -> 第9桌
A19: =總表!O75 -> 第1車 | B19: =總表!C75 -> 馬英傑 | C19: =總表!D75 -> 富亨通訊處 | D19: =總表!E75 -> 男 | E19: =總表!A75 -> 36 | F19: =總表!B75 -> 71 | G19: =總表!H75 -> 第2桌 | H19: =總表!I75 -> 第9桌
A20: =總表!O74 -> 第1車 | B20: =總表!C74 -> 張家瑋 | C20: =總表!D74 -> 富亨通訊處 | D20: =總表!E74 -> 男 | E20: =總表!A74 -> 35 | F20: =總表!B74 -> 70 | G20: =總表!H74 -> 第2桌 | H20: =總表!I74 -> 第3桌
A21: =總表!O76 -> 第1車 | B21: =總表!C76 -> 林宏威 | C21: =總表!D76 -> 富亨通訊處 | D21: =總表!E76 -> 男 | E21: =總表!A76 -> 36 | F21: =總表!B76 -> 72 | G21: =總表!H76 -> 第2桌 | H21: =總表!I76 -> 第6桌
A22: =總表!O71 -> 第1車 | B22: =總表!C71 -> 張祐珮 | C22: =總表!D71 -> 富后通訊處 | D22: =總表!E71 -> 女 | E22: =總表!A71 -> 34 | F22: =總表!B71 -> 67 | G22: =總表!H71 -> 第2桌 | H22: =總表!I71 -> 第8桌
A23: =總表!O73 -> 第1車 | B23: =總表!C73 -> 吳皓誠 | C23: =總表!D73 -> 富亨通訊處 | D23: =總表!E73 -> 男 | E23: =總表!A73 -> 35 | F23: =總表!B73 -> 69 | G23: =總表!H73 -> 第2桌 | H23: =總表!I73 -> 第1桌
A24: =總表!O72 -> 第1車 | B24: =總表!C72 -> 施昕余 | C24: =總表!D72 -> 中銘通訊處 | D24: =總表!E72 -> 女 | E24: =總表!A72 -> 34 | F24: =總表!B72 -> 68 | G24: =總表!H72 -> 第2桌 | H24: =總表!I72 -> 第4桌
A25: =總表!O51 -> 第1車 | B25: =總表!C51 -> 傅佳旻 | C25: =總表!D51 -> 富占通訊處 | D25: =總表!E51 -> 女 | E25: =總表!A51 -> 24 | F25: =總表!B51 -> 47 | G25: =總表!H51 -> 第3桌 | H25: =總表!I51 -> 第8桌
A26: =總表!O52 -> 第1車 | B26: =總表!C52 -> 徐維鈴 | C26: =總表!D52 -> 富占通訊處 | D26: =總表!E52 -> 女 | E26: =總表!A52 -> 24 | F26: =總表!B52 -> 48 | G26: =總表!H52 -> 第3桌 | H26: =總表!I52 -> 第1桌
A27: =總表!O87 -> 第1車 | B27: =總表!C87 -> 范毓斌 | C27: =總表!D87 -> 富占通訊處 | D27: =總表!E87 -> 男 | E27: =總表!A87 -> 42 | F27: =總表!B87 -> 83 | G27: =總表!H87 -> 第3桌 | H27: =總表!I87 -> 第4桌
A28: =總表!O85 -> 第1車 | B28: =總表!C85 -> 鄭占禮 | C28: =總表!D85 -> 富占通訊處 | D28: =總表!E85 -> 男 | E28: =總表!A85 -> 41 | F28: =總表!B85 -> 81 | G28: =總表!H85 -> 第3桌 | H28: =總表!I85 -> 主桌
A29: =總表!O53 -> 第1車 | B29: =總表!C53 -> 鍾怡婷 | C29: =總表!D53 -> 富占通訊處 | D29: =總表!E53 -> 女 | E29: =總表!A53 -> 25 | F29: =總表!B53 -> 49 | G29: =總表!H53 -> 第3桌 | H29: =總表!I53 -> 第6桌
A30: =總表!O54 -> 第1車 | B30: =總表!C54 -> 林宜潔 | C30: =總表!D54 -> 富占通訊處 | D30: =總表!E54 -> 女 | E30: =總表!A54 -> 25 | F30: =總表!B54 -> 50 | G30: =總表!H54 -> 第3桌 | H30: =總表!I54 -> 第9桌
A31: =總表!O66 -> 第1車 | B31: =總表!C66 -> 張國興 | C31: =總表!D66 -> 富則通訊處 | D31: =總表!E66 -> 男 | E31: =總表!A66 -> 31 | F31: =總表!B66 -> 62 | G31: =總表!H66 -> 第3桌 | H31: =總表!I66 -> 第4桌
A32: =總表!O86 -> 第1車 | B32: =總表!C86 -> 孫振文 | C32: =總表!D86 -> 富北通訊處 | D32: =總表!E86 -> 男 | E32: =總表!A86 -> 41 | F32: =總表!B86 -> 82 | G32: =總表!H86 -> 第3桌 | H32: =總表!I86 -> 主桌
A33: =總表!O45 -> 第1車 | B33: =總表!C45 -> 簡宏鈞 | C33: =總表!D45 -> 富能通訊處 | D33: =總表!E45 -> 男 | E33: =總表!A45 -> 21 | F33: =總表!B45 -> 41 | G33: =總表!H45 -> 第3桌 | H33: =總表!I45 -> 主桌
A34: =總表!O65 -> 第1車 | B34: =總表!C65 -> 蔡承遠 | C34: =總表!D65 -> 富則通訊處 | D34: =總表!E65 -> 男 | E34: =總表!A65 -> 31 | F34: =總表!B65 -> 61 | G34: =總表!H65 -> 第3桌 | H34: =總表!I65 -> 第9桌
A35: =總表!O80 -> 第1車 | B35: =總表!C80 -> 葉金玲 | C35: =總表!D80 -> 富鑽通訊處 | D35: =總表!E80 -> 女 | E35: =總表!A80 -> 38 | F35: =總表!B80 -> 76 | G35: =總表!H80 -> 第4桌 | H35: =總表!I80 -> 第1桌
A36: =總表!O79 -> 第1車 | B36: =總表!C79 -> 陳龍生 | C36: =總表!D79 -> 富鑽通訊處 | D36: =總表!E79 -> 男 | E36: =總表!A79 -> 38 | F36: =總表!B79 -> 75 | G36: =總表!H79 -> 第4桌 | H36: =總表!I79 -> 第6桌
A37: =總表!O82 -> 第1車 | B37: =總表!C82 -> 林瑋 | C37: =總表!D82 -> 富北通訊處 | D37: =總表!E82 -> 男 | E37: =總表!A82 -> 39 | F37: =總表!B82 -> 78 | G37: =總表!H82 -> 第4桌 | H37: =總表!I82 -> 第2桌
A38: =總表!O81 -> 第1車 | B38: =總表!C81 -> 吳士侃 | C38: =總表!D81 -> 富北通訊處 | D38: =總表!E81 -> 男 | E38: =總表!A81 -> 39 | F38: =總表!B81 -> 77 | G38: =總表!H81 -> 第4桌 | H38: =總表!I81 -> 第7桌
A39: =總表!O47 -> 第1車 | B39: =總表!C47 -> 管卓鈞 | C39: =總表!D47 -> 富能通訊處 | D39: =總表!E47 -> 女 | E39: =總表!A47 -> 22 | F39: =總表!B47 -> 43 | G39: =總表!H47 -> 第4桌 | H39: =總表!I47 -> 第5桌
A40: =總表!O49 -> 第1車 | B40: =總表!C49 -> 簡姵萱 | C40: =總表!D49 -> 富能通訊處 | D40: =總表!E49 -> 女 | E40: =總表!A49 -> 23 | F40: =總表!B49 -> 45 | G40: =總表!H49 -> 第4桌 | H40: =總表!I49 -> 第7桌
A41: =總表!O50 -> 第1車 | B41: =總表!C50 -> 潘韻竹 | C41: =總表!D50 -> 富則通訊處 | D41: =總表!E50 -> 女 | E41: =總表!A50 -> 23 | F41: =總表!B50 -> 46 | G41: =總表!H50 -> 第4桌 | H41: =總表!I50 -> 第8桌
...
